Workbook

Sheet 里程碑计划
A2: 时间 | B2: 45139 | F2: 45170 | J2: 45200 | O2: 45231 | S2: 45261 | W2: 45292 | AB2: 45323
B3: 7 | C3: =B3+7 -> 14 | D3: =C3+7 -> 21 | E3: =D3+7 -> 28 | F3: 4 | G3: =F3+7 -> 11 | H3: =G3+7 -> 18 | I3: =H3+7 -> 25 | J3: 2 | K3: =J3+7 -> 9 | L3: =K3+7 -> 16 | M3: =L3+7 -> 23 | N3: =M3+7 -> 30 | O3: 6 | P3: =O3+7 -> 13 | Q3: =P3+7 -> 20 | R3: =Q3+7 -> 27 | S3: 4 | T3: =S3+7 -> 11 | U3: =T3+7 -> 18 | V3: =U3+7 -> 25 | W3: 1 | X3: =W3+7 -> 8 | Y3: =X3+7 -> 15 | Z3: =Y3+7 -> 22 | AA3: =Z3+7 -> 29 | AB3: 5 | AC3: =AB3+7 -> 12 | AD3: =AC3+7 -> 19 | AE3: =AD3+7 -> 26
A5: 实施
A6: 开发
A7: 用户&IT
A9: 里程碑节点说明
A10: 序号 | B10: 里程碑 | E10: 开始时间 | G10: 结束时间 | I10: 天数
A11: 1 | E11: 45292 | G11: 45311 | I11: =NETWORKDAYS(E11,G11,法定节假日!B2:B33) -> 14
A12: 2 | I12: =NETWORKDAYS(E12,G12,法定节假日!B2:B33) -> 0
A13: 3 | I13: =NETWORKDAYS(E13,G13,法定节假日!B2:B33) -> 0
A14: 4 | I14: =NETWORKDAYS(E14,G14,法定节假日!B2:B33) -> 0
A15: 5 | I15: =NETWORKDAYS(E15,G15,法定节假日!B2:B33) -> 0

Sheet 主计划
A1: 一级流程 （阶段） | B1: 二级流程 （场景） | C1: 三级流程 （任务） | D1: 任务名称 | E1: 后置 | F1: 前置 | G1: 进度 | I1: 里程碑 | J1: 乙方 评审 | K1: 甲方 评审 | L1: PMO | M1: 计划时间 | O1: 工作日 | P1: 是否与上个任务为前后置关系 | Q1: 执行人 | S1: 关键交付物
G2: 状态 | H2: 进度备注 | M2: 计划开始 | N2: 计划结束 | O2: 计划天数 | Q2: 主责 | R2: 协助或支持
A3: 1 | D3: 项目准备 | G3: =IF(COUNTIF(G4:G15,"未完成")=COUNTA(G4:G15),"未完成",IF(COUNTIF(G4:G15,"已完成")=COUNTA(G4:G15),"已完成","进行中")) -> 未完成 | M3: 45172 | N3: =_xlfn.WORKDAY.INTL(M3,O3,1,法定节假日!B2:B31) -> 45202 | O3: 22
B4: 1.1 | D4: 内部启动 | G4: =项目准备WBS!S3 -> 未完成 | M4: =M3 -> 45172 | N4: =_xlfn.WORKDAY.INTL(M4,O4,1,法定节假日!B2:B31) -> 45177 | O4: 5
A5: ★ | C5: 1.1.1 | D5: 内部启动准备 | G5: =IF(COUNTIF(项目准备WBS!S4:S9,"未完成")=COUNTA(项目准备WBS!S4:S9),"未完成",IF(COUNTIF(项目准备WBS!S4:S9,"已完成")=COUNTA(项目准备WBS!S4:S9),"已完成","进行中")) -> 未完成 | J5: √ | M5: 45172 | N5: =_xlfn.WORKDAY.INTL(M5,O5,1,法定节假日!B2:B31) -> 45175 | O5: 3
A6: ★ | C6: 1.1.2 | D6: 内部启动会 | G6: =IF(COUNTIF(项目准备WBS!S10:S11,"未完成")=COUNTA(项目准备WBS!S10:S11),"未完成",IF(COUNTIF(项目准备WBS!S10:S11,"已完成")=COUNTA(项目准备WBS!S10:S11),"已完成","进行中")) -> 未完成 | J6: √ | L6: √ | M6: =IF(P6="是",N5,"") -> 45175 | N6: =_xlfn.WORKDAY.INTL(M6,O6,1,法定节假日!B2:B31) -> 45177 | O6: 2 | P6: 是
B7: 1.2 | D7: 技术准备 | G7: =项目准备WBS!S12 -> 未完成 | M7: 45180 | N7: =_xlfn.WORKDAY.INTL(M7,O7,1,法定节假日!B2:B31) -> 45189 | O7: 7
A8: ★ | C8: 1.2.1 | D8: 用户业务流程获取 | G8: =项目准备WBS!S13 -> 未完成 | M8: 45178 | N8: =_xlfn.WORKDAY.INTL(M8,O8,1,法定节假日!B2:B31) -> 45181 | O8: 2
A9: ★ | C9: 1.2.2 | D9: 交付物V0.1准备 | G9: =IF(COUNTIF(项目准备WBS!S14:S15,"未完成")=COUNTA(项目准备WBS!S14:S15),"未完成",IF(COUNTIF(项目准备WBS!S14:S15,"已完成")=COUNTA(项目准备WBS!S14:S15),"已完成","进行中")) -> 未完成 | J9: √ | L9: √ | M9: =IF(P9="是",N8,"") -> 45181 | N9: =_xlfn.WORKDAY.INTL(M9,O9,1,法定节假日!B2:B31) -> 45184 | O9: 3 | P9: 是 | S9: 《交付物V0.1》
A10: ★ | C10: 1.2.3 | D10: 调研问卷准备 | G10: =IF(COUNTIF(项目准备WBS!S16:S17,"未完成")=COUNTA(项目准备WBS!S16:S17),"未完成",IF(COUNTIF(项目准备WBS!S16:S17,"已完成")=COUNTA(项目准备WBS!S16:S17),"已完成","进行中")) -> 未完成 | J10: √ | L10: √ | M10: =IF(P10="是",N9,"") -> 45184 | N10: =_xlfn.WORKDAY.INTL(M10,O10,1,法定节假日!B2:B31) -> 45195 | O10: 7 | P10: 是 | S10: 《调研问卷》
B11: 1.3 | D11: 项目启动 | G11: =项目准备WBS!S18 -> 未完成 | M11: 45174 | N11: =_xlfn.WORKDAY.INTL(M11,O11,1,法定节假日!B2:B31) -> 45177 | O11: 3
A12: ★ | C12: 1.3.1 | D12: 组建客户团队 | G12: =项目准备WBS!S19 -> 未完成 | K12: √ | M12: =M11 -> 45174 | N12: =_xlfn.WORKDAY.INTL(M12,O12,1,法定节假日!B2:B31) -> 45182 | O12: 6 | S12: 《项目章程》
A13: ★ | C13: 1.3.2 | D13: 客户方准备办公环境 | G13: =项目准备WBS!S20 -> 未完成 | M13: =IF(P13="是",N12,"") -> 45182 | N13: =_xlfn.WORKDAY.INTL(M13,O13,1,法定节假日!B2:B31) -> 45189 | O13: 5 | P13: 是
A14: ★ | C14: 1.3.3 | D14: 项目管理规划 | G14: =项目准备WBS!S21 -> 未完成 | K14: √ | L14: √ | M14: =IF(P14="是",N13,"") | N14: =_xlfn.WORKDAY.INTL(M14,O14,1,法定节假日!B2:B31) -> #VALUE! | S14: 《项目管理方案》
A15: ★ | C15: 1.3.4 | D15: 召开启动会 | G15: =IF(COUNTIF(项目准备WBS!S22:S24,"未完成")=COUNTA(项目准备WBS!S22:S24),"未完成",IF(COUNTIF(项目准备WBS!S22:S24,"已完成")=COUNTA(项目准备WBS!S22:S24),"已完成","进行中")) -> 未完成 | I15: √ | J15: √ | K15: √ | L15: √ | M15: =IF(P15="是",N14,"") | N15: =_xlfn.WORKDAY.INTL(M15,O15,1,法定节假日!B2:B31) -> #VALUE! | S15: 《项目启动会PPT》
A16: 2 | D16: 需求分析 | G16: =IF(COUNTIF(G17:G38,"未完成")=COUNTA(G17:G38),"未完成",IF(COUNTIF(G17:G38,"已完成")=COUNTA(G17:G38),"已完成","进行中")) -> 未完成 | N16: =_xlfn.WORKDAY.INTL(M16,O16,1,法定节假日!B2:B31) -> 0
B17: 2.1 | D17: 业务调研与分析 | G17: =需求分析WBS!S3 -> 未完成 | N17: =_xlfn.WORKDAY.INTL(M17,O17,1,法定节假日!B2:B31) -> 0
A18: ★ | C18: 2.1.1 | D18: 调研资料准备 | F18: 1.2.3 | G18: =IF(COUNTIF(需求分析WBS!S4:S5,"未完成")=COUNTA(需求分析WBS!S4:S5),"未完成",IF(COUNTIF(需求分析WBS!S4:S5,"已完成")=COUNTA(需求分析WBS!S4:S5),"已完成","进行中")) -> 未完成 | N18: =_xlfn.WORKDAY.INTL(M18,O18,1,法定节假日!B2:B31) -> 0
A19: ★ | C19: 2.1.2 | D19: 关键用户培训考核 | G19: =IF(COUNTIF(需求分析WBS!S6:S7,"未完成")=COUNTA(需求分析WBS!S6:S7),"未完成",IF(COUNTIF(需求分析WBS!S6:S7,"已完成")=COUNTA(需求分析WBS!S6:S7),"已完成","进行中")) -> 未完成 | M19: =IF(P19="是",N18,"") | N19: =_xlfn.WORKDAY.INTL(M19,O19,1,法定节假日!B2:B31) -> #VALUE!
A20: ★ | C20: 2.1.3 | D20: 业务调研与模拟分析 | F20: 1.2.1 | G20: =IF(COUNTIF(需求分析WBS!S8:S12,"未完成")=COUNTA(需求分析WBS!S8:S12),"未完成",IF(COUNTIF(需求分析WBS!S8:S12,"已完成")=COUNTA(需求分析WBS!S8:S12),"已完成","进行中")) -> 未完成 | M20: =IF(P20="是",N19,"") | N20: =_xlfn.WORKDAY.INTL(M20,O20,1,法定节假日!B2:B31) -> #VALUE! | S20: 《调研纪要》
A21: ★ | C21: 2.1.4 | D21: 调研分析报告制定与评审 | G21: =IF(COUNTIF(需求分析WBS!S13:S16,"未完成")=COUNTA(需求分析WBS!S13:S16),"未完成",IF(COUNTIF(需求分析WBS!S13:S16,"已完成")=COUNTA(需求分析WBS!S13:S16),"已完成","进行中")) -> 未完成 | J21: √ | K21: √ | L21: √ | M21: =IF(P21="是",N20,"") | N21: =_xlfn.WORKDAY.INTL(M21,O21,1,法定节假日!B2:B31) -> #VALUE! | S21: 《调研分析报告》
B22: 2.2 | D22: 系统蓝图设计 | G22: =需求分析WBS!S17 -> 未完成 | M22: =IF(P22="是",N21,"") | N22: =_xlfn.WORKDAY.INTL(M22,O22,1,法定节假日!B2:B31) -> #VALUE!
A23: ★ | C23: 2.2.1 | D23: 需求确认与应答 | G23: =IF(COUNTIF(需求分析WBS!S18:S19,"未完成")=COUNTA(需求分析WBS!S18:S19),"未完成",IF(COUNTIF(需求分析WBS!S18:S19,"已完成")=COUNTA(需求分析WBS!S18:S19),"已完成","进行中")) -> 未完成 | L23: √ | N23: =_xlfn.WORKDAY.INTL(M23,O23,1,法定节假日!B2:B31) -> 0 | S23: 《需求清单》《URS需求应答》
A24: ★ | C24: 2.2.2 | D24: 蓝图设计报告制定 | G24: =IF(COUNTIF(需求分析WBS!S20:S23,"未完成")=COUNTA(需求分析WBS!S20:S23),"未完成",IF(COUNTIF(需求分析WBS!S20:S23,"已完成")=COUNTA(需求分析WBS!S20:S23),"已完成","进行中")) -> 未完成 | L24: √ | M24: =IF(P24="是",N23,"") | N24: =_xlfn.WORKDAY.INTL(M24,O24,1,法定节假日!B2:B31) -> #VALUE! | S24: 《蓝图设计报告》
A25: ★ | C25: 2.2.3 | D25: 蓝图评审与签字确认 | G25: =IF(COUNTIF(需求分析WBS!S24:S25,"未完成")=COUNTA(需求分析WBS!S24:S25),"未完成",IF(COUNTIF(需求分析WBS!S24:S25,"已完成")=COUNTA(需求分析WBS!S24:S25),"已完成","进行中")) -> 未完成 | I25: √ | J25: √ | K25: √ | L25: √ | M25: =IF(P25="是",N24,"") | N25: =_xlfn.WORKDAY.INTL(M25,O25,1,法定节假日!B2:B31) -> #VALUE! | S25: 《蓝图验收确认单》
B26: 2.3 | D26: 接口详细设计 | G26: =需求分析WBS!S26 -> 未完成 | M26: =IF(P26="是",N25,"") | N26: =_xlfn.WORKDAY.INTL(M26,O26,1,法定节假日!B2:B31) -> #VALUE!
A27: ★ | C27: 2.3.1 | D27: 接口清单及字段确认 | G27: =IF(COUNTIF(需求分析WBS!S27:S28,"未完成")=COUNTA(需求分析WBS!S27:S28),"未完成",IF(COUNTIF(需求分析WBS!S27:S28,"已完成")=COUNTA(需求分析WBS!S27:S28),"已完成","进行中")) -> 未完成 | N27: =_xlfn.WORKDAY.INTL(M27,O27,1,法定节假日!B2:B31) -> 0
A28: ★ | C28: 2.3.2 | D28: 接口详设文档制定与评审 | G28: =IF(COUNTIF(需求分析WBS!S29:S33,"未完成")=COUNTA(需求分析WBS!S29:S33),"未完成",IF(COUNTIF(需求分析WBS!S29:S33,"已完成")=COUNTA(需求分析WBS!S29:S33),"已完成","进行中")) -> 未完成 | J28: √ | K28: √ | L28: √ | M28: =IF(P28="是",N27,"") | N28: =_xlfn.WORKDAY.INTL(M28,O28,1,法定节假日!B2:B31) -> #VALUE! | S28: 《接口详细设计文档》
B29: 2.4 | D29: 输入数据处理与收集 | G29: =需求分析WBS!S34 -> 未完成 | M29: =IF(P29="是",N28,"") | N29: =_xlfn.WORKDAY.INTL(M29,O29,1,法定节假日!B2:B31) -> #VALUE!
A30: ★ | C30: 2.4.1 | D30: 数据收集模板制定与评审 | G30: =IF(COUNTIF(需求分析WBS!S35:S37,"未完成")=COUNTA(需求分析WBS!S35:S37),"未完成",IF(COUNTIF(需求分析WBS!S35:S37,"已完成")=COUNTA(需求分析WBS!S35:S37),"已完成","进行中")) -> 未完成 | K30: √ | N30: =_xlfn.WORKDAY.INTL(M30,O30,1,法定节假日!B2:B31) -> 0 | S30: 《数据收集模板》
A31: ★ | C31: 2.4.2 | D31: 少量产品数据收集与验证 | G31: =IF(COUNTIF(需求分析WBS!S38:S40,"未完成")=COUNTA(需求分析WBS!S38:S40),"未完成",IF(COUNTIF(需求分析WBS!S38:S40,"已完成")=COUNTA(需求分析WBS!S38:S40),"已完成","进行中")) -> 未完成 | M31: =IF(P31="是",N30,"") | N31: =_xlfn.WORKDAY.INTL(M31,O31,1,法定节假日!B2:B31) -> #VALUE!
A32: ★ | C32: 2.4.3 | D32: 接口接入数据管理方案制定 | G32: =IF(COUNTIF(需求分析WBS!S41:S43,"未完成")=COUNTA(需求分析WBS!S41:S43),"未完成",IF(COUNTIF(需求分析WBS!S41:S43,"已完成")=COUNTA(需求分析WBS!S41:S43),"已完成","进行中")) -> 未完成 | J32: √ | K32: √ | L32: √ | M32: =IF(P32="是",N31,"") | N32: =_xlfn.WORKDAY.INTL(M32,O32,1,法定节假日!B2:B31) -> #VALUE! | S32: 《接口接入数据管理方案》
A33: ★ | C33: 2.4.4 | D33: 对接系统数据处理与验证 | G33: =需求分析WBS!S44 -> 未完成 | M33: =IF(P33="是",N32,"") | N33: =_xlfn.WORKDAY.INTL(M33,O33,1,法定节假日!B2:B31) -> #VALUE!
A34: ★ | C34: 2.4.5 | D34: 全量产品数据与规则收集 | E34: 4.1.2 | G34: =IF(COUNTIF(需求分析WBS!S45:S46,"未完成")=COUNTA(需求分析WBS!S45:S46),"未完成",IF(COUNTIF(需求分析WBS!S45:S46,"已完成")=COUNTA(需求分析WBS!S45:S46),"已完成","进行中")) -> 未完成 | N34: =_xlfn.WORKDAY.INTL(M34,O34,1,法定节假日!B2:B31) -> 0 | S34: 《全量数据收集表》
B35: 2.5 | D35: 运行环境准备 | G35: =需求分析WBS!S47 -> 未完成 | M35: =IF(P35="是",N34,"") | N35: =_xlfn.WORKDAY.INTL(M35,O35,1,法定节假日!B2:B31) -> #VALUE!
A36: ★ | C36: 2.5.1 | D36: 运行环境需求确认 | G36: =需求分析WBS!S48 -> 未完成 | N36: =_xlfn.WORKDAY.INTL(M36,O36,1,法定节假日!B2:B31) -> 0 | S36: 《服务器配置需求》
A37: ★ | C37: 2.5.2 | D37: 客户IT环境准备 | G37: =需求分析WBS!S49 -> 未完成 | M37: =IF(P37="是",N36,"") | N37: =_xlfn.WORKDAY.INTL(M37,O37,1,法定节假日!B2:B31) -> #VALUE!
A38: ★ | C38: 2.5.3 | D38: 网络访问准备 | G38: =IF(COUNTIF(需求分析WBS!S50:S52,"未完成")=COUNTA(需求分析WBS!S50:S52),"未完成",IF(COUNTIF(需求分析WBS!S50:S52,"已完成")=COUNTA(需求分析WBS!S50:S52),"已完成","进行中")) -> 未完成 | M38: =IF(P38="是",N37,"") | N38: =_xlfn.WORKDAY.INTL(M38,O38,1,法定节假日!B2:B31) -> #VALUE! | S38: 《网络访问信息表》
A39: 3 | D39: 系统实现 | G39: =IF(COUNTIF(G40:G52,"未完成")=COUNTA(G40:G52),"未完成",IF(COUNTIF(G40:G52,"已完成")=COUNTA(G40:G52),"已完成","进行中")) -> 未完成 | N39: =_xlfn.WORKDAY.INTL(M39,O39,1,法定节假日!B2:B31) -> 0
B40: 3.1 | D40: 系统实现准备 | G40: =系统实现WBS!S3 -> 未完成 | N40: =_xlfn.WORKDAY.INTL(M40,O40,1,法定节假日!B2:B31) -> 0
...

Sheet 项目准备WBS
A1: 二级流程 （场景） | B1: 三级流程 （任务） | C1: 任务名称 | D1: WBS | E1: 说明 | F1: 里程碑 | G1: 乙方 评审 | H1: 甲方 评审 | I1: PMO | J1: 计划时间 | L1: 工作日 | M1: 是否与上个任务为前后置关系 | N1: 实际时间 | P1: 工作日 | Q1: 执行人 | S1: 进度 | U1: 交付物
J2: 计划开始 | K2: 计划结束 | L2: 计划天数 | N2: 实际开始 | O2: 实际完成 | P2: 实际天数 | Q2: 主责 | R2: 协助或支持 | S2: 状态 | T2: 进度备注
A3: 1.1 | C3: 内部启动 | J3: =主计划!M4 -> 45172 | K3: =主计划!N4 -> 45177 | L3: =主计划!O4 -> 5 | N3: =MIN(N4:N11) -> 0 | O3: =MAX(O4:O11) -> 0 | P3: =NETWORKDAYS(N3,O3) -> 0 | S3: =IF(COUNTIF(S4:S11,"未完成")=COUNTA(S4:S11),"未完成",IF(COUNTIF(S4:S11,"已完成")=COUNTA(S4:S11),"已完成","进行中")) -> 未完成
B4: 1.1.1 | C4: 内部启动准备 | D4: 选择团队成员 | J4: 45172 | K4: =_xlfn.WORKDAY.INTL(J4,L4,1,法定节假日!B2:B31) -> 45172 | P4: =NETWORKDAYS(N4,O4) -> 0 | S4: 未完成
D5: 组织售前交接会 | I5: √ | J5: =IF(M5="是",K4,"") | K5: =_xlfn.WORKDAY.INTL(J5,L5,1,法定节假日!B2:B31) -> #VALUE! | P5: =NETWORKDAYS(N5,O5) -> 0 | S5: 未完成
D6: 制度模板裁剪 | I6: √ | J6: =IF(M6="是",K5,"") | K6: =_xlfn.WORKDAY.INTL(J6,L6,1,法定节假日!B2:B31) -> #VALUE! | P6: =NETWORKDAYS(N6,O6) -> 0 | S6: 未完成
D7: 项目基线制定 | J7: =IF(M7="是",K6,"") | K7: =_xlfn.WORKDAY.INTL(J7,L7,1,法定节假日!B2:B31) -> #VALUE! | P7: =NETWORKDAYS(N7,O7) -> 0 | S7: 未完成
D8: 项目基线评审 | G8: √ | I8: √ | J8: =IF(M8="是",K7,"") | K8: =_xlfn.WORKDAY.INTL(J8,L8,1,法定节假日!B2:B31) -> #VALUE! | P8: =NETWORKDAYS(N8,O8) -> 0 | S8: 未完成
D9: CRM建项 | I9: √ | J9: =IF(M9="是",K8,"") | K9: =_xlfn.WORKDAY.INTL(J9,L9,1,法定节假日!B2:B31) -> #VALUE! | P9: =NETWORKDAYS(N9,O9) -> 0 | S9: 未完成
B10: 1.1.2 | C10: 内部启动会 | D10: 内部启动材料准备 | I10: √ | J10: =IF(M10="是",K9,"") | K10: =_xlfn.WORKDAY.INTL(J10,L10,1,法定节假日!B2:B31) -> #VALUE! | P10: =NETWORKDAYS(N10,O10) -> 0 | S10: 未完成
D11: 组织内部启动会 | G11: √ | I11: √ | J11: =IF(M11="是",K10,"") | K11: =_xlfn.WORKDAY.INTL(J11,L11,1,法定节假日!B2:B31) -> #VALUE! | P11: =NETWORKDAYS(N11,O11) -> 0 | S11: 未完成
A12: 1.2 | C12: 技术准备 | J12: =主计划!M7 -> 45180 | K12: =主计划!N7 -> 45189 | L12: =主计划!O7 -> 7 | N12: =MIN(N13:N17) -> 0 | O12: =MAX(O13:O17) -> 0 | P12: =NETWORKDAYS(N12,O12) -> 0 | S12: =IF(COUNTIF(S13:S17,"未完成")=COUNTA(S13:S17),"未完成",IF(COUNTIF(S13:S17,"已完成")=COUNTA(S13:S17),"已完成","进行中")) -> 未完成
B13: 1.2.1 | C13: 用户业务流程获取 | D13: 用户业务流程获取 | J13: =主计划!M8 -> 45178 | K13: =主计划!N8 -> 45181 | P13: =NETWORKDAYS(N13,O13) -> 0 | S13: 未完成
B14: 1.2.2 | C14: 交付物V0.1准备 | D14: 交付物V0.1制定 | J14: =IF(M14="是",K13,"") | K14: =_xlfn.WORKDAY.INTL(J14,L14,1,法定节假日!B2:B31) -> #VALUE! | P14: =NETWORKDAYS(N14,O14) -> 0 | S14: 未完成
D15: 技术顾问评审 | G15: √ | I15: √ | J15: =IF(M15="是",K14,"") | K15: =_xlfn.WORKDAY.INTL(J15,L15,1,法定节假日!B2:B31) -> #VALUE! | P15: =NETWORKDAYS(N15,O15) -> 0 | S15: 未完成
B16: 1.2.3 | C16: 调研问卷准备 | D16: 调研问卷准备 | J16: =IF(M16="是",K15,"") | K16: =_xlfn.WORKDAY.INTL(J16,L16,1,法定节假日!B2:B31) -> #VALUE! | P16: =NETWORKDAYS(N16,O16) -> 0 | S16: 未完成
D17: 技术顾问评审 | G17: √ | I17: √ | J17: =IF(M17="是",K16,"") | K17: =_xlfn.WORKDAY.INTL(J17,L17,1,法定节假日!B2:B31) -> #VALUE! | P17: =NETWORKDAYS(N17,O17) -> 0 | S17: 未完成
A18: 1.3 | C18: 项目启动 | J18: =主计划!M11 -> 45174 | K18: =主计划!N11 -> 45177 | L18: =主计划!O11 -> 3 | N18: =MIN(N19:N24) -> 0 | O18: =MAX(O19:O24) -> 0 | P18: =NETWORKDAYS(N18,O18) -> 0 | S18: =IF(COUNTIF(S19:S24,"未完成")=COUNTA(S19:S24),"未完成",IF(COUNTIF(S19:S24,"已完成")=COUNTA(S19:S24),"已完成","进行中")) -> 未完成
B19: 1.3.1 | C19: 组建客户团队 | D19: 指导组建客户团队 | H19: √ | J19: =主计划!M12 -> 45174 | K19: =主计划!N12 -> 45182 | P19: =NETWORKDAYS(N19,O19) -> 0 | S19: 未完成
B20: 1.3.2 | C20: 客户方准备办公环境 | D20: 客户办公环境准备 | J20: =主计划!M13 -> 45182 | K20: =主计划!N13 -> 45189 | P20: =NETWORKDAYS(N20,O20) -> 0 | S20: 未完成
B21: 1.3.3 | C21: 项目管理规划 | D21: 项目管理方案确定 | H21: √ | I21: √ | J21: =主计划!M14 | K21: =主计划!N14 -> #VALUE! | P21: =NETWORKDAYS(N21,O21) -> 0 | S21: 未完成
B22: 1.3.4 | C22: 召开启动会 | D22: 启动会流程讨论 | J22: =IF(M22="是",K21,"") | K22: =_xlfn.WORKDAY.INTL(J22,L22,1,法定节假日!B2:B31) -> #VALUE! | P22: =NETWORKDAYS(N22,O22) -> 0 | S22: 未完成
D23: 启动会PPT制作与同行评审 | G23: √ | H23: √ | I23: √ | J23: =IF(M23="是",K22,"") | K23: =_xlfn.WORKDAY.INTL(J23,L23,1,法定节假日!B2:B31) -> #VALUE! | P23: =NETWORKDAYS(N23,O23) -> 0 | S23: 未完成
D24: 召开启动会 | F24: √ | J24: =IF(M24="是",K23,"") | K24: =_xlfn.WORKDAY.INTL(J24,L24,1,法定节假日!B2:B31) -> #VALUE! | P24: =NETWORKDAYS(N24,O24) -> 0 | S24: 未完成

Sheet 需求分析WBS
A1: 二级流程 （场景） | B1: 三级流程 （任务） | C1: 任务名称 | D1: WBS | E1: 说明 | F1: 里程碑 | G1: 乙方 评审 | H1: 甲方 评审 | I1: PMO 监控&评审点 | J1: 计划时间 | L1: 工作日 | M1: 是否与上个任务为前后置关系 | N1: 实际时间 | P1: 工作日 | Q1: 执行人 | S1: 进度 | U1: 交付物
J2: 计划开始 | K2: 计划结束 | L2: 计划天数 | N2: 实际开始 | O2: 实际完成 | P2: 实际天数 | Q2: 主责 | R2: 协助或支持 | S2: 状态 | T2: 进度备注
A3: 2.1 | C3: 业务调研与分析 | J3: =主计划!M17 -> 0 | K3: =主计划!N17 -> 0 | L3: =主计划!O17 -> 0 | N3: =MIN(N4:N16) -> 0 | O3: =MAX(O4:O16) -> 0 | P3: =NETWORKDAYS(N3,O3) -> 0 | S3: =IF(COUNTIF(S4:S16,"未完成")=COUNTA(S4:S16),"未完成",IF(COUNTIF(S4:S16,"已完成")=COUNTA(S4:S16),"已完成","进行中")) -> 未完成
B4: 2.1.1 | C4: 调研资料准备 | D4: 调研问卷用户确认 | K4: =_xlfn.WORKDAY.INTL(J4,L4,1,法定节假日!B2:B31) -> 0 | P4: =NETWORKDAYS(N4,O4) -> 0 | S4: 未完成
D5: 用户调研计划制定与评审 | J5: =IF(M5="是",K4,"") | K5: =_xlfn.WORKDAY.INTL(J5,L5,1,法定节假日!B2:B31) -> #VALUE! | P5: =NETWORKDAYS(N5,O5) -> 0 | S5: 未完成
B6: 2.2.2 | C6: 关于用户培训考核 | D6: 关键用户培训准备 | E6: 教材、考试题、签到表 | J6: =IF(M6="是",K5,"") | K6: =_xlfn.WORKDAY.INTL(J6,L6,1,法定节假日!B2:B31) -> #VALUE! | P6: =NETWORKDAYS(N6,O6) -> 0 | S6: 未完成
D7: 关键用户培训与考核 | J7: =IF(M7="是",K6,"") | K7: =_xlfn.WORKDAY.INTL(J7,L7,1,法定节假日!B2:B31) -> #VALUE! | P7: =NETWORKDAYS(N7,O7) -> 0 | S7: 未完成
B8: 2.2.3 | C8: 业务调研与模拟分析 | D8: 业务调研与纪要确认 | E8: 按用户调研计划执行 | J8: =IF(M8="是",K7,"") | K8: =_xlfn.WORKDAY.INTL(J8,L8,1,法定节假日!B2:B31) -> #VALUE! | P8: =NETWORKDAYS(N8,O8) -> 0 | S8: 未完成
D9: 业务场景流程梳理与差异分析 | J9: =IF(M9="是",K8,"") | K9: =_xlfn.WORKDAY.INTL(J9,L9,1,法定节假日!B2:B31) -> #VALUE! | P9: =NETWORKDAYS(N9,O9) -> 0 | S9: 未完成
D10: 排产规则梳理与模拟确认 | J10: =IF(M10="是",K9,"") | K10: =_xlfn.WORKDAY.INTL(J10,L10,1,法定节假日!B2:B31) -> #VALUE! | P10: =NETWORKDAYS(N10,O10) -> 0 | S10: 未完成
D11: 业务优化策略梳理与确认 | J11: =IF(M11="是",K10,"") | K11: =_xlfn.WORKDAY.INTL(J11,L11,1,法定节假日!B2:B31) -> #VALUE! | P11: =NETWORKDAYS(N11,O11) -> 0 | S11: 未完成
D12: 接口清单梳理与确认 | J12: =IF(M12="是",K11,"") | K12: =_xlfn.WORKDAY.INTL(J12,L12,1,法定节假日!B2:B31) -> #VALUE! | P12: =NETWORKDAYS(N12,O12) -> 0 | S12: 未完成
B13: 2.2.4 | C13: 调研分析报告制定与评审 | D13: 调研分析报告制定 | J13: =IF(M13="是",K12,"") | K13: =_xlfn.WORKDAY.INTL(J13,L13,1,法定节假日!B2:B31) -> #VALUE! | P13: =NETWORKDAYS(N13,O13) -> 0 | S13: 未完成
D14: 技术顾问评审确认 | J14: =IF(M14="是",K13,"") | K14: =_xlfn.WORKDAY.INTL(J14,L14,1,法定节假日!B2:B31) -> #VALUE! | P14: =NETWORKDAYS(N14,O14) -> 0 | S14: 未完成
D15: 关键用户评审确认 | G15: √ | H15: √ | I15: √ | J15: =IF(M15="是",K14,"") | K15: =_xlfn.WORKDAY.INTL(J15,L15,1,法定节假日!B2:B31) -> #VALUE! | P15: =NETWORKDAYS(N15,O15) -> 0 | S15: 未完成
D16: 谷斗内部评审确认 | H16: √ | J16: =IF(M16="是",K15,"") | K16: =_xlfn.WORKDAY.INTL(J16,L16,1,法定节假日!B2:B31) -> #VALUE! | P16: =NETWORKDAYS(N16,O16) -> 0 | S16: 未完成
A17: 2.2 | C17: 系统蓝图设计 | J17: =主计划!M22 | K17: =主计划!N22 -> #VALUE! | L17: =主计划!O22 -> 0 | N17: =MIN(N18:N25) -> 0 | O17: =MAX(O18:O25) -> 0 | P17: =NETWORKDAYS(N17,O17) -> 0 | S17: =IF(COUNTIF(S18:S25,"未完成")=COUNTA(S18:S25),"未完成",IF(COUNTIF(S18:S25,"已完成")=COUNTA(S18:S25),"已完成","进行中")) -> 未完成
B18: 2.2.1 | C18: 需求确认与应答 | D18: 需求清单编写与确认 | G18: √ | H18: √ | I18: √ | K18: =_xlfn.WORKDAY.INTL(J18,L18,1,法定节假日!B2:B31) -> 0 | P18: =NETWORKDAYS(N18,O18) -> 0 | S18: 未完成
D19: URS需求应答编写与确认 | G19: √ | H19: √ | I19: √ | J19: =IF(M19="是",K18,"") | K19: =_xlfn.WORKDAY.INTL(J19,L19,1,法定节假日!B2:B31) -> #VALUE! | P19: =NETWORKDAYS(N19,O19) -> 0 | S19: 未完成
B20: 2.2.2 | C20: 蓝图设计报告制定 | D20: 蓝图设计报告制定 | J20: =IF(M20="是",K19,"") | K20: =_xlfn.WORKDAY.INTL(J20,L20,1,法定节假日!B2:B31) -> #VALUE! | P20: =NETWORKDAYS(N20,O20) -> 0 | S20: 未完成
D21: 技术顾问同行评审 | J21: =IF(M21="是",K20,"") | K21: =_xlfn.WORKDAY.INTL(J21,L21,1,法定节假日!B2:B31) -> #VALUE! | P21: =NETWORKDAYS(N21,O21) -> 0 | S21: 未完成
D22: 关键用户同行评审 | H22: √ | J22: =IF(M22="是",K21,"") | K22: =_xlfn.WORKDAY.INTL(J22,L22,1,法定节假日!B2:B31) -> #VALUE! | P22: =NETWORKDAYS(N22,O22) -> 0 | S22: 未完成
D23: 谷斗内部同行评审 | G23: √ | I23: √ | J23: =IF(M23="是",K22,"") | K23: =_xlfn.WORKDAY.INTL(J23,L23,1,法定节假日!B2:B31) -> #VALUE! | P23: =NETWORKDAYS(N23,O23) -> 0 | S23: 未完成
B24: 2.2.3 | C24: 蓝图客户评审签字 | D24: 正式评审汇报 | H24: √ | J24: =IF(M24="是",K23,"") | K24: =_xlfn.WORKDAY.INTL(J24,L24,1,法定节假日!B2:B31) -> #VALUE! | P24: =NETWORKDAYS(N24,O24) -> 0 | S24: 未完成
D25: 评审完成签字 | I25: √ | J25: =IF(M25="是",K24,"") | K25: =_xlfn.WORKDAY.INTL(J25,L25,1,法定节假日!B2:B31) -> #VALUE! | P25: =NETWORKDAYS(N25,O25) -> 0 | S25: 未完成
A26: 2.3 | C26: 接口详细设计 | J26: =主计划!M26 | K26: =主计划!N26 -> #VALUE! | L26: =主计划!O26 -> 0 | N26: =MIN(N27:N33) -> 0 | O26: =MAX(O27:O33) -> 0 | P26: =NETWORKDAYS(N26,O26) -> 0 | S26: =IF(COUNTIF(S27:S33,"未完成")=COUNTA(S27:S33),"未完成",IF(COUNTIF(S27:S33,"已完成")=COUNTA(S27:S33),"已完成","进行中")) -> 未完成
B27: 2.3.1 | C27: 接口清单及字段确认 | D27: 接口清单确认 | K27: =_xlfn.WORKDAY.INTL(J27,L27,1,法定节假日!B2:B31) -> 0 | P27: =NETWORKDAYS(N27,O27) -> 0 | S27: 未完成
D28: 接口清单字段确认 | J28: =IF(M28="是",K27,"") | K28: =_xlfn.WORKDAY.INTL(J28,L28,1,法定节假日!B2:B31) -> #VALUE! | P28: =NETWORKDAYS(N28,O28) -> 0 | S28: 未完成
B29: 2.3.2 | C29: 接口详设文档制定与评审 | D29: 接口详设文档制定 | J29: =IF(M29="是",K28,"") | K29: =_xlfn.WORKDAY.INTL(J29,L29,1,法定节假日!B2:B31) -> #VALUE! | P29: =NETWORKDAYS(N29,O29) -> 0 | S29: 未完成
D30: 技术顾问同行评审 | J30: =IF(M30="是",K29,"") | K30: =_xlfn.WORKDAY.INTL(J30,L30,1,法定节假日!B2:B31) -> #VALUE! | P30: =NETWORKDAYS(N30,O30) -> 0 | S30: 未完成
D31: 关键用户同行评审 | J31: =IF(M31="是",K30,"") | K31: =_xlfn.WORKDAY.INTL(J31,L31,1,法定节假日!B2:B31) -> #VALUE! | P31: =NETWORKDAYS(N31,O31) -> 0 | S31: 未完成
D32: 谷斗内部同行评审 | G32: √ | I32: √ | J32: =IF(M32="是",K31,"") | K32: =_xlfn.WORKDAY.INTL(J32,L32,1,法定节假日!B2:B31) -> #VALUE! | P32: =NETWORKDAYS(N32,O32) -> 0 | S32: 未完成
D33: 用户正式评审确认 | J33: =IF(M33="是",K32,"") | K33: =_xlfn.WORKDAY.INTL(J33,L33,1,法定节假日!B2:B31) -> #VALUE! | P33: =NETWORKDAYS(N33,O33) -> 0 | S33: 未完成
A34: 2.4 | C34: 输入数据处理与收集 | J34: =主计划!M29 | K34: =主计划!N29 -> #VALUE! | L34: =主计划!O29 -> 0 | N34: =MIN(N35:N46) -> 0 | O34: =MAX(O35:O46) -> 0 | P34: =NETWORKDAYS(N34,O34) -> 0 | S34: =IF(COUNTIF(S35:S46,"未完成")=COUNTA(S35:S46),"未完成",IF(COUNTIF(S35:S46,"已完成")=COUNTA(S35:S46),"已完成","进行中")) -> 未完成
B35: 2.4.1 | C35: 数据收集模板制定与评审 | D35: 基础规则收集模板制定与确认 | H35: √ | K35: =_xlfn.WORKDAY.INTL(J35,L35,1,法定节假日!B2:B31) -> 0 | P35: =NETWORKDAYS(N35,O35) -> 0 | S35: 未完成
D36: 新增规则模板制定与确认 | J36: =IF(M36="是",K35,"") | K36: =_xlfn.WORKDAY.INTL(J36,L36,1,法定节假日!B2:B31) -> #VALUE! | P36: =NETWORKDAYS(N36,O36) -> 0 | S36: 未完成
D37: 接口接入数据收集清单确认 | J37: =IF(M37="是",K36,"") | K37: =_xlfn.WORKDAY.INTL(J37,L37,1,法定节假日!B2:B31) -> #VALUE! | P37: =NETWORKDAYS(N37,O37) -> 0 | S37: 未完成
B38: 2.4.2 | C38: 少量产品数据收集与验证 | D38: 少量产品数据用户收集 | J38: =IF(M38="是",K37,"") | K38: =_xlfn.WORKDAY.INTL(J38,L38,1,法定节假日!B2:B31) -> #VALUE! | P38: =NETWORKDAYS(N38,O38) -> 0 | S38: 未完成
D39: 产品demo验证与确认 | J39: =IF(M39="是",K38,"") | K39: =_xlfn.WORKDAY.INTL(J39,L39,1,法定节假日!B2:B31) -> #VALUE! | P39: =NETWORKDAYS(N39,O39) -> 0 | S39: 未完成
D40: 数据收集模板调整 | J40: =IF(M40="是",K39,"") | K40: =_xlfn.WORKDAY.INTL(J40,L40,1,法定节假日!B2:B31) -> #VALUE! | P40: =NETWORKDAYS(N40,O40) -> 0 | S40: 未完成
...

Sheet 系统实现WBS
A1: 二级流程 （场景） | B1: 三级流程 （任务） | C1: 任务名称 | D1: WBS | E1: 说明 | F1: 里程碑 | G1: 乙方 评审 | H1: 甲方 评审 | I1: PMO 监控&评审点 | J1: 计划时间 | L1: 工作日 | M1: 是否与上个任务为前后置关系 | N1: 实际时间 | P1: 工作日 | Q1: 执行人 | S1: 进度 | U1: 交付物
J2: 计划开始 | K2: 计划结束 | L2: 计划天数 | N2: 实际开始 | O2: 实际完成 | P2: 实际天数 | Q2: 主责 | R2: 协助或支持 | S2: 状态 | T2: 进度备注
A3: 3.1 | C3: 系统实现准备 | J3: =主计划!M40 -> 0 | K3: =主计划!N40 -> 0 | L3: =主计划!O40 -> 0 | N3: =MIN(N4:N9) -> 0 | O3: =MAX(O4:O9) -> 0 | P3: =NETWORKDAYS(N3,O3) -> 0 | S3: =IF(COUNTIF(S4:S9,"未完成")=COUNTA(S4:S9),"未完成",IF(COUNTIF(S4:S9,"已完成")=COUNTA(S4:S9),"已完成","进行中")) -> 未完成
B4: 3.1.1 | C4: 开发设计及工时预估 | D4: 开发功能设计 | K4: =_xlfn.WORKDAY.INTL(J4,L4,1,法定节假日!B2:B31) -> 0 | P4: =NETWORKDAYS(N4,O4) -> 0 | S4: 未完成
D5: 功能工时估算 | J5: =IF(M5="是",K4,"") | K5: =_xlfn.WORKDAY.INTL(J5,L5,1,法定节假日!B2:B31) -> #VALUE! | P5: =NETWORKDAYS(N5,O5) -> 0 | S5: 未完成
D6: 开发设计评审 | G6: √ | I6: √ | J6: =IF(M6="是",K5,"") | K6: =_xlfn.WORKDAY.INTL(J6,L6,1,法定节假日!B2:B31) -> #VALUE! | P6: =NETWORKDAYS(N6,O6) -> 0 | S6: 未完成
B7: 3.1.2 | C7: 需求版本及发布计划确认 | D7: 需求版本制定与确认 | J7: =IF(M7="是",K6,"") | K7: =_xlfn.WORKDAY.INTL(J7,L7,1,法定节假日!B2:B31) -> #VALUE! | P7: =NETWORKDAYS(N7,O7) -> 0 | S7: 未完成
D8: 发布计划制定与确认 | G8: √ | H8: √ | I8: √ | J8: =IF(M8="是",K7,"") | K8: =_xlfn.WORKDAY.INTL(J8,L8,1,法定节假日!B2:B31) -> #VALUE! | P8: =NETWORKDAYS(N8,O8) -> 0 | S8: 未完成
D9: 禅道需求和任务创建 | I9: √ | J9: =IF(M9="是",K8,"") | K9: =_xlfn.WORKDAY.INTL(J9,L9,1,法定节假日!B2:B31) -> #VALUE! | P9: =NETWORKDAYS(N9,O9) -> 0 | S9: 未完成
A10: 3.2 | C10: 版本开发与用户测试 | J10: =主计划!M43 | K10: =主计划!N43 -> #VALUE! | L10: =主计划!O43 -> 0 | N10: =MIN(N11:N18) -> 0 | O10: =MAX(O11:O18) -> 0 | P10: =NETWORKDAYS(N10,O10) -> 0 | S10: =IF(COUNTIF(S11:S18,"未完成")=COUNTA(S11:S18),"未完成",IF(COUNTIF(S11:S18,"已完成")=COUNTA(S11:S18),"已完成","进行中")) -> 未完成
B11: 3.2.1 | C11: 开发测试数据准备 | D11: 测试用例制定与确认 | K11: =_xlfn.WORKDAY.INTL(J11,L11,1,法定节假日!B2:B31) -> 0 | P11: =NETWORKDAYS(N11,O11) -> 0 | S11: 未完成
D12: 测试数据准备与确认 | J12: =IF(M12="是",K11,"") | K12: =_xlfn.WORKDAY.INTL(J12,L12,1,法定节假日!B2:B31) -> #VALUE! | P12: =NETWORKDAYS(N12,O12) -> 0 | S12: 未完成
D13: 接口postman联调 | J13: =IF(M13="是",K12,"") | K13: =_xlfn.WORKDAY.INTL(J13,L13,1,法定节假日!B2:B31) -> #VALUE! | P13: =NETWORKDAYS(N13,O13) -> 0 | S13: 未完成
B14: 3.2.2 | C14: 开发实现与测试确认 | D14: 开发实现与测试确认 | J14: =主计划!M45 | K14: =主计划!N45 -> #VALUE! | L14: =主计划!O45 -> 0 | P14: =NETWORKDAYS(N14,O14) -> 0 | S14: 未完成
B15: 3.2.3 | C15: 顾问单元测试与确认 | D15: 顾问单元测试与确认 | J15: =主计划!M46 | K15: =主计划!N46 -> #VALUE! | L15: =主计划!O46 -> 0 | P15: =NETWORKDAYS(N15,O15) -> 0 | S15: 未完成
B16: 3.2.4 | C16: 用户单元测试与确认 | D16: 功能部署与配置 | J16: =IF(M16="是",K15,"") | K16: =_xlfn.WORKDAY.INTL(J16,L16,1,法定节假日!B2:B31) -> #VALUE! | P16: =NETWORKDAYS(N16,O16) -> 0 | S16: 未完成
D17: 组织用户培训与确认 | J17: =IF(M17="是",K16,"") | K17: =_xlfn.WORKDAY.INTL(J17,L17,1,法定节假日!B2:B31) -> #VALUE! | P17: =NETWORKDAYS(N17,O17) -> 0 | S17: 未完成
D18: 用户单元测试与确认 | J18: =IF(M18="是",K17,"") | K18: =_xlfn.WORKDAY.INTL(J18,L18,1,法定节假日!B2:B31) -> #VALUE! | P18: =NETWORKDAYS(N18,O18) -> 0 | S18: 未完成
A19: 3.3 | C19: 用户集成测试 | J19: =主计划!M48 | K19: =主计划!N48 -> #VALUE! | L19: =主计划!O48 -> 0 | N19: =MIN(N20:N32) -> 0 | O19: =MAX(O20:O32) -> 0 | P19: =NETWORKDAYS(N19,O19) -> 0 | S19: =IF(COUNTIF(S20:S32,"未完成")=COUNTA(S20:S32),"未完成",IF(COUNTIF(S20:S32,"已完成")=COUNTA(S20:S32),"已完成","进行中")) -> 未完成
B20: 3.3.1 | C20: 关键用户培训考核 | D20: 关键用户培训准备 | K20: =_xlfn.WORKDAY.INTL(J20,L20,1,法定节假日!B2:B31) -> 0 | P20: =NETWORKDAYS(N20,O20) -> 0 | S20: 未完成
D21: 关键用户培训与考核 | J21: =IF(M21="是",K20,"") | K21: =_xlfn.WORKDAY.INTL(J21,L21,1,法定节假日!B2:B31) -> #VALUE! | P21: =NETWORKDAYS(N21,O21) -> 0 | S21: 未完成
B22: 3.3.2 | C22: 业务场景拉通测试 | D22: 场景测试计划制定与确认 | J22: =IF(M22="是",K21,"") | K22: =_xlfn.WORKDAY.INTL(J22,L22,1,法定节假日!B2:B31) -> #VALUE! | P22: =NETWORKDAYS(N22,O22) -> 0 | S22: 未完成
D23: 测试用例制定与确认 | J23: =IF(M23="是",K22,"") | K23: =_xlfn.WORKDAY.INTL(J23,L23,1,法定节假日!B2:B31) -> #VALUE! | P23: =NETWORKDAYS(N23,O23) -> 0 | S23: 未完成
D24: 测试数据准备与确认 | J24: =IF(M24="是",K23,"") | K24: =_xlfn.WORKDAY.INTL(J24,L24,1,法定节假日!B2:B31) -> #VALUE! | P24: =NETWORKDAYS(N24,O24) -> 0 | S24: 未完成
D25: 系统功能及优化确认 | J25: =IF(M25="是",K24,"") | K25: =_xlfn.WORKDAY.INTL(J25,L25,1,法定节假日!B2:B31) -> #VALUE! | P25: =NETWORKDAYS(N25,O25) -> 0 | S25: 未完成
D26: 场景测试与报告确认 | J26: =IF(M26="是",K25,"") | K26: =_xlfn.WORKDAY.INTL(J26,L26,1,法定节假日!B2:B31) -> #VALUE! | P26: =NETWORKDAYS(N26,O26) -> 0 | S26: 未完成
B27: 3.3.3 | C27: 系统联调测试（全量） | D27: 联调测试计划制定与确认 | J27: =IF(M27="是",K26,"") | K27: =_xlfn.WORKDAY.INTL(J27,L27,1,法定节假日!B2:B31) -> #VALUE! | P27: =NETWORKDAYS(N27,O27) -> 0 | S27: 未完成
D28: 测试用例制定与确认 | J28: =IF(M28="是",K27,"") | K28: =_xlfn.WORKDAY.INTL(J28,L28,1,法定节假日!B2:B31) -> #VALUE! | P28: =NETWORKDAYS(N28,O28) -> 0 | S28: 未完成
D29: 测试数据准备与确认 | J29: =IF(M29="是",K28,"") | K29: =_xlfn.WORKDAY.INTL(J29,L29,1,法定节假日!B2:B31) -> #VALUE! | P29: =NETWORKDAYS(N29,O29) -> 0 | S29: 未完成
D30: 系统配置与通讯准备 | J30: =IF(M30="是",K29,"") | K30: =_xlfn.WORKDAY.INTL(J30,L30,1,法定节假日!B2:B31) -> #VALUE! | P30: =NETWORKDAYS(N30,O30) -> 0 | S30: 未完成
D31: 接口测试与报告确认 | J31: =IF(M31="是",K30,"") | K31: =_xlfn.WORKDAY.INTL(J31,L31,1,法定节假日!B2:B31) -> #VALUE! | P31: =NETWORKDAYS(N31,O31) -> 0 | S31: 未完成
B32: 3.3.4 | C32: 功能交付确认 | D32: 功能交付清单确认 | G32: √ | H32: √ | I32: √ | J32: =主计划!M52 | K32: =主计划!N52 -> #VALUE! | L32: =主计划!O52 -> 0 | P32: =NETWORKDAYS(N32,O32) -> 0 | S32: 未完成
B33: 3.3.5 | K33: =主计划!N53 -> 0 | P33: =NETWORKDAYS(N33,O33) -> 0 | S33: 未完成

Sheet UAT试运行WBS
A1: 二级流程 （场景） | B1: 三级流程 （任务） | C1: 任务名称 | D1: WBS | E1: 说明 | F1: 里程碑 | G1: 乙方 评审 | H1: 甲方 评审 | I1: PMO 监控&评审点 | J1: 计划时间 | L1: 工作日 | M1: 是否与上个任务为前后置关系 | N1: 实际时间 | P1: 工作日 | Q1: 执行人 | S1: 进度 | U1: 交付物
J2: 计划开始 | K2: 计划结束 | L2: 计划天数 | N2: 实际开始 | O2: 实际完成 | P2: 实际天数 | Q2: 主责 | R2: 协助或支持 | S2: 状态 | T2: 进度备注
A3: 4.1 | C3: UAT/试运行 | J3: =主计划!M55 -> 0 | K3: =主计划!N55 -> 0 | L3: =主计划!O55 -> 0 | N3: =MIN(N4:N11) -> 0 | O3: =MAX(O4:O11) -> 0 | P3: =NETWORKDAYS(N3,O3) -> 0 | S3: =IF(COUNTIF(S4:S11,"未完成")=COUNTA(S4:S11),"未完成",IF(COUNTIF(S4:S11,"已完成")=COUNTA(S4:S11),"已完成","进行中")) -> 未完成
C4: 试运行计划制定 | D4: 试运行计划制定与确认 | G4: √ | H4: √ | I4: √ | J4: =主计划!M56 -> 0 | K4: =主计划!N56 -> 0 | L4: =主计划!O56 -> 0 | P4: =NETWORKDAYS(N4,O4) -> 0 | S4: 未完成
C5: 全量数据测试准备 | D5: 产品与规则系统导入与验证 | J5: =IF(M5="是",K4,"") | K5: =_xlfn.WORKDAY.INTL(J5,L5,1,法定节假日!B2:B31) -> #VALUE! | P5: =NETWORKDAYS(N5,O5) -> 0 | S5: 未完成
D6: 业务数据全量导入 | J6: =IF(M6="是",K5,"") | K6: =_xlfn.WORKDAY.INTL(J6,L6,1,法定节假日!B2:B31) -> #VALUE! | P6: =NETWORKDAYS(N6,O6) -> 0 | S6: 未完成
D7: 销售数据准备与导入 | J7: =IF(M7="是",K6,"") | K7: =_xlfn.WORKDAY.INTL(J7,L7,1,法定节假日!B2:B31) -> #VALUE! | P7: =NETWORKDAYS(N7,O7) -> 0 | S7: 未完成
D8: 全量系统优化排产验证 | J8: =IF(M8="是",K7,"") | K8: =_xlfn.WORKDAY.INTL(J8,L8,1,法定节假日!B2:B31) -> #VALUE! | P8: =NETWORKDAYS(N8,O8) -> 0 | S8: 未完成
C9: 系统试运行及确认 | D9: 各计划结果合理性确认 | J9: =IF(M9="是",K8,"") | K9: =_xlfn.WORKDAY.INTL(J9,L9,1,法定节假日!B2:B31) -> #VALUE! | P9: =NETWORKDAYS(N9,O9) -> 0 | S9: 未完成
D10: 试运行报告签字确认 | H10: √ | I10: √ | J10: =IF(M10="是",K9,"") | K10: =_xlfn.WORKDAY.INTL(J10,L10,1,法定节假日!B2:B31) -> #VALUE! | P10: =NETWORKDAYS(N10,O10) -> 0 | S10: 未完成
C11: 测试问题结果确认 | D11: 测试问题结果确认 | J11: =主计划!M59 | K11: =主计划!N59 -> #VALUE! | L11: =主计划!O59 -> 0 | P11: =NETWORKDAYS(N11,O11) -> 0 | S11: 未完成
A12: 4.2 | C12: 最终用户培训 | J12: =主计划!M60 | K12: =主计划!N60 -> #VALUE! | L12: =主计划!O60 -> 0 | N12: =MIN(N13:N15) -> 0 | O12: =MAX(O13:O15) -> 0 | P12: =NETWORKDAYS(N12,O12) -> 0 | S12: =IF(COUNTIF(S13:S15,"未完成")=COUNTA(S13:S15),"未完成",IF(COUNTIF(S13:S15,"已完成")=COUNTA(S13:S15),"已完成","进行中")) -> 未完成
C13: 最终用户培训考核 | D13: 最终用户培训准备 | K13: =_xlfn.WORKDAY.INTL(J13,L13,1,法定节假日!B2:B31) -> 0 | P13: =NETWORKDAYS(N13,O13) -> 0 | S13: 未完成
D14: 最终用户培训与考核 | J14: =IF(M14="是",K13,"") | K14: =_xlfn.WORKDAY.INTL(J14,L14,1,法定节假日!B2:B31) -> #VALUE! | P14: =NETWORKDAYS(N14,O14) -> 0 | S14: 未完成
C15: 用户操作手册制定 | D15: 操作手册撰写与顾问评审 | G15: √ | H15: √ | I15: √ | J15: =主计划!M62 | K15: =主计划!N62 -> #VALUE! | L15: =主计划!O62 -> 0 | P15: =NETWORKDAYS(N15,O15) -> 0 | S15: 未完成
A16: 4.3 | C16: 上线准备 | J16: =主计划!M63 | K16: =主计划!N63 -> #VALUE! | L16: =主计划!O63 -> 0 | N16: =MAX(N17:N29) -> 0 | O16: =MIN(O17:O29) -> 0 | P16: =NETWORKDAYS(N16,O16) -> 0 | S16: =IF(COUNTIF(S17:S29,"未完成")=COUNTA(S17:S29),"未完成",IF(COUNTIF(S17:S29,"已完成")=COUNTA(S17:S29),"已完成","进行中")) -> 未完成
C17: 制定上线策略与切换计划 | D17: 上线策略与切换计划制定 | G17: √ | H17: √ | I17: √ | K17: =_xlfn.WORKDAY.INTL(J17,L17,1,法定节假日!B2:B31) -> 0 | P17: =NETWORKDAYS(N17,O17) -> 0 | S17: 未完成
D18: 上线应急策略制定 | H18: √ | J18: =IF(M18="是",K17,"") | K18: =_xlfn.WORKDAY.INTL(J18,L18,1,法定节假日!B2:B31) -> #VALUE! | P18: =NETWORKDAYS(N18,O18) -> 0 | S18: 未完成
C19: 初始化数据准备与测试 | D19: 初始化数据清单确认 | J19: =IF(M19="是",K18,"") | K19: =_xlfn.WORKDAY.INTL(J19,L19,1,法定节假日!B2:B31) -> #VALUE! | P19: =NETWORKDAYS(N19,O19) -> 0 | S19: 未完成
D20: 初始化数据验证指南 | J20: =IF(M20="是",K19,"") | K20: =_xlfn.WORKDAY.INTL(J20,L20,1,法定节假日!B2:B31) -> #VALUE! | P20: =NETWORKDAYS(N20,O20) -> 0 | S20: 未完成
D21: xxxx数据收集与测试 | J21: =IF(M21="是",K20,"") | K21: =_xlfn.WORKDAY.INTL(J21,L21,1,法定节假日!B2:B31) -> #VALUE! | P21: =NETWORKDAYS(N21,O21) -> 0 | S21: 未完成
C22: 准备正式生产环境 | D22: 服务器配置确认 | J22: =IF(M22="是",K21,"") | K22: =_xlfn.WORKDAY.INTL(J22,L22,1,法定节假日!B2:B31) -> #VALUE! | P22: =NETWORKDAYS(N22,O22) -> 0 | S22: 未完成
D23: 服务器端口开放确认 | J23: =IF(M23="是",K22,"") | K23: =_xlfn.WORKDAY.INTL(J23,L23,1,法定节假日!B2:B31) -> #VALUE! | P23: =NETWORKDAYS(N23,O23) -> 0 | S23: 未完成
D24: 平台部署与自查 | J24: =IF(M24="是",K23,"") | K24: =_xlfn.WORKDAY.INTL(J24,L24,1,法定节假日!B2:B31) -> #VALUE! | P24: =NETWORKDAYS(N24,O24) -> 0 | S24: 未完成
D25: 模型部署与检查 | J25: =IF(M25="是",K24,"") | K25: =_xlfn.WORKDAY.INTL(J25,L25,1,法定节假日!B2:B31) -> #VALUE! | P25: =NETWORKDAYS(N25,O25) -> 0 | S25: 未完成
D26: 数据库安装与检查 | J26: =IF(M26="是",K25,"") | K26: =_xlfn.WORKDAY.INTL(J26,L26,1,法定节假日!B2:B31) -> #VALUE! | P26: =NETWORKDAYS(N26,O26) -> 0 | S26: 未完成
D27: 系统登录确认 | J27: =IF(M27="是",K26,"") | K27: =_xlfn.WORKDAY.INTL(J27,L27,1,法定节假日!B2:B31) -> #VALUE! | P27: =NETWORKDAYS(N27,O27) -> 0 | S27: 未完成
D28: 网络通畅确认 | J28: =IF(M28="是",K27,"") | K28: =_xlfn.WORKDAY.INTL(J28,L28,1,法定节假日!B2:B31) -> #VALUE! | P28: =NETWORKDAYS(N28,O28) -> 0 | S28: 未完成
C29: 上线启动商讨会 | D29: 上线启动商讨会 | J29: =主计划!M67 | K29: =主计划!N67 -> #VALUE! | L29: =主计划!O67 -> 0 | P29: =NETWORKDAYS(N29,O29) -> 0 | S29: 未完成
A30: 4.4 | C30: 系统上线 | J30: =主计划!M68 | K30: =主计划!N68 -> #VALUE! | L30: =主计划!O68 -> 0 | N30: =MIN(N31:N37) -> 0 | O30: =MAX(O31:O37) -> 0 | P30: =NETWORKDAYS(N30,O30) -> 0 | S30: =IF(COUNTIF(S31:S37,"未完成")=COUNTA(S31:S37),"未完成",IF(COUNTIF(S31:S37,"已完成")=COUNTA(S31:S37),"已完成","进行中")) -> 未完成
C31: 正式环境数据导入与优化确认 | D31: 模型场景页面视图配置 | K31: =_xlfn.WORKDAY.INTL(J31,L31,1,法定节假日!B2:B31) -> 0 | P31: =NETWORKDAYS(N31,O31) -> 0 | S31: 未完成
D32: xxxx数据导入与验证 | J32: =IF(M32="是",K31,"") | K32: =_xlfn.WORKDAY.INTL(J32,L32,1,法定节假日!B2:B31) -> #VALUE! | P32: =NETWORKDAYS(N32,O32) -> 0 | S32: 未完成
D33: 系统优化结果确认 | J33: =IF(M33="是",K32,"") | K33: =_xlfn.WORKDAY.INTL(J33,L33,1,法定节假日!B2:B31) -> #VALUE! | P33: =NETWORKDAYS(N33,O33) -> 0 | S33: 未完成
C34: 召开上线动员大会 | D34: 启动会材料制作与同行评审 | G34: √ | H34: √ | I34: √ | J34: =IF(M34="是",K33,"") | K34: =_xlfn.WORKDAY.INTL(J34,L34,1,法定节假日!B2:B31) -> #VALUE! | P34: =NETWORKDAYS(N34,O34) -> 0 | S34: 未完成
D35: 召开上线启动会 | J35: =IF(M35="是",K34,"") | K35: =_xlfn.WORKDAY.INTL(J35,L35,1,法定节假日!B2:B31) -> #VALUE! | P35: =NETWORKDAYS(N35,O35) -> 0 | S35: 未完成
C36: 通知正式启用新系统 | D36: 通知正式启用新系统 | J36: =主计划!M71 | K36: =主计划!N71 -> #VALUE! | L36: =主计划!O71 -> 0 | P36: =NETWORKDAYS(N36,O36) -> 0 | S36: 未完成
C37: 签署上线确认单 | D37: 签署上线确认单 | F37: √ | I37: √ | J37: =主计划!M72 | K37: =主计划!N72 -> #VALUE! | L37: =主计划!O72 -> 0 | P37: =NETWORKDAYS(N37,O37) -> 0 | S37: 未完成

Sheet 上线运行WBS
A1: 二级流程 （场景） | B1: 三级流程 （任务） | C1: 任务名称 | D1: WBS | E1: 说明 | F1: 里程碑 | G1: 乙方 评审 | H1: 甲方 评审 | I1: PMO 监控&评审点 | J1: 计划时间 | L1: 工作日 | M1: 是否与上个任务为前后置关系 | N1: 实际时间 | P1: 工作日 | Q1: 执行人 | S1: 进度 | U1: 交付物
J2: 计划开始 | K2: 计划结束 | L2: 计划天数 | N2: 实际开始 | O2: 实际完成 | P2: 实际天数 | Q2: 主责 | R2: 协助或支持 | S2: 状态 | T2: 进度备注
A3: 5.1 | C3: 辅导与验收 | J3: =主计划!M74 -> 0 | K3: =主计划!N74 -> 0 | L3: =主计划!O74 -> 0 | N3: =MIN(N4:N17) -> 0 | O3: =MAX(O4:O17) -> 0 | P3: =NETWORKDAYS(N3,O3) -> 0 | S3: =IF(COUNTIF(S4:S17,"未完成")=COUNTA(S4:S17),"未完成",IF(COUNTIF(S4:S17,"已完成")=COUNTA(S4:S17),"已完成","进行中")) -> 未完成
C4: 验收策略确认 | I4: √ | J4: =主计划!M75 -> 0 | K4: =主计划!N75 -> 0 | L4: =主计划!O75 -> 0 | P4: =NETWORKDAYS(N4,O4) -> 0 | S4: 未完成
C5: 用户应用指导与定期复盘 | D5: 项目复盘材料制定 | J5: =IF(M5="是",K4,"") | K5: =_xlfn.WORKDAY.INTL(J5,L5,1,法定节假日!B3:B32) -> #VALUE! | P5: =NETWORKDAYS(N5,O5) -> 0 | S5: 未完成
D6: 组织召开复盘会议 | J6: =IF(M6="是",K5,"") | K6: =_xlfn.WORKDAY.INTL(J6,L6,1,法定节假日!B4:B33) -> #VALUE! | P6: =NETWORKDAYS(N6,O6) -> 0 | S6: 未完成
D7: 总结问题并发布指导手册 | J7: =IF(M7="是",K6,"") | K7: =_xlfn.WORKDAY.INTL(J7,L7,1,法定节假日!B5:B34) -> #VALUE! | P7: =NETWORKDAYS(N7,O7) -> 0 | S7: 未完成
C8: 实施文档基线确认 | D8: 确认交付文档清单 | J8: =IF(M8="是",K7,"") | K8: =_xlfn.WORKDAY.INTL(J8,L8,1,法定节假日!B6:B35) -> #VALUE! | P8: =NETWORKDAYS(N8,O8) -> 0 | S8: 未完成
D9: 整理项目交付文档 | J9: =IF(M9="是",K8,"") | K9: =_xlfn.WORKDAY.INTL(J9,L9,1,法定节假日!B7:B36) -> #VALUE! | P9: =NETWORKDAYS(N9,O9) -> 0 | S9: 未完成
D10: URS需求应答-状态确认 | J10: =IF(M10="是",K9,"") | K10: =_xlfn.WORKDAY.INTL(J10,L10,1,法定节假日!B8:B37) -> #VALUE! | P10: =NETWORKDAYS(N10,O10) -> 0 | S10: 未完成
D11: 项目文档基线确认 | J11: =IF(M11="是",K10,"") | K11: =_xlfn.WORKDAY.INTL(J11,L11,1,法定节假日!B9:B38) -> #VALUE! | P11: =NETWORKDAYS(N11,O11) -> 0 | S11: 未完成
C12: 项目验收评审 | D12: 准备验收评审材料 | G12: √ | H12: √ | I12: √ | J12: =IF(M12="是",K11,"") | K12: =_xlfn.WORKDAY.INTL(J12,L12,1,法定节假日!B10:B39) -> #VALUE! | P12: =NETWORKDAYS(N12,O12) -> 0 | S12: 未完成
D13: 组织项目验收评审 | H13: √ | J13: =IF(M13="是",K12,"") | K13: =_xlfn.WORKDAY.INTL(J13,L13,1,法定节假日!B11:B40) -> #VALUE! | P13: =NETWORKDAYS(N13,O13) -> 0 | S13: 未完成
C14: 召开项目总结表彰 | D14: 会议流程讨论 | J14: =IF(M14="是",K13,"") | K14: =_xlfn.WORKDAY.INTL(J14,L14,1,法定节假日!B13:B41) -> #VALUE! | P14: =NETWORKDAYS(N14,O14) -> 0 | S14: 未完成
D15: 表彰会材料制作与同行评审 | G15: √ | H15: √ | I15: √ | J15: =IF(M15="是",K14,"") | K15: =_xlfn.WORKDAY.INTL(J15,L15,1,法定节假日!B16:B42) -> #VALUE! | P15: =NETWORKDAYS(N15,O15) -> 0 | S15: 未完成
D16: 召开项目总结表彰会 | J16: =IF(M16="是",K15,"") | K16: =_xlfn.WORKDAY.INTL(J16,L16,1,法定节假日!B17:B43) -> #VALUE! | P16: =NETWORKDAYS(N16,O16) -> 0 | S16: 未完成
C17: 签署验收确认单 | D17: 签署验收确认单 | F17: √ | I17: √ | J17: =主计划!M80 | K17: =主计划!N80 -> #VALUE! | L17: =主计划!O80 -> 0 | P17: =NETWORKDAYS(N17,O17) -> 0 | S17: 未完成
A18: 5.2 | C18: 项目收尾 | J18: =主计划!M81 | K18: =主计划!N81 -> #VALUE! | N18: =MIN(N19:N25) -> 0 | O18: =MAX(O19:O25) -> 0 | P18: =NETWORKDAYS(N18,O18) -> 0 | S18: =IF(COUNTIF(S19:S25,"未完成")=COUNTA(S19:S25),"未完成",IF(COUNTIF(S19:S25,"已完成")=COUNTA(S19:S25),"已完成","进行中")) -> 未完成
C19: 移交项目资料给客户 | J19: =主计划!M82 -> 0 | K19: =主计划!N82 -> 0 | L19: =主计划!O82 -> 0 | P19: =NETWORKDAYS(N19,O19) -> 0 | S19: 未完成
C20: 内部分享与总结归档 | D20: 系统功能分享-内部 | I20: √ | J20: =IF(M20="是",K19,"") | K20: =_xlfn.WORKDAY.INTL(J20,L20,1,法定节假日!B21:B47) -> #VALUE! | P20: =NETWORKDAYS(N20,O20) -> 0 | S20: 未完成
D21: 项目组工作总结-内部 | I21: √ | J21: =IF(M21="是",K20,"") | K21: =_xlfn.WORKDAY.INTL(J21,L21,1,法定节假日!B22:B48) -> #VALUE! | P21: =NETWORKDAYS(N21,O21) -> 0 | S21: 未完成
D22: 更新组织过程资产-内部 | I22: √ | J22: =IF(M22="是",K21,"") | K22: =_xlfn.WORKDAY.INTL(J22,L22,1,法定节假日!B23:B49) -> #VALUE! | P22: =NETWORKDAYS(N22,O22) -> 0 | S22: 未完成
C23: 奖惩兑现与团队解散 | J23: =主计划!M84 | K23: =主计划!N84 -> #VALUE! | L23: =主计划!O84 -> 0 | P23: =NETWORKDAYS(N23,O23) -> 0 | S23: 未完成
C24: 实施转持续服务交接 | D24: 实施转持续服务交接 | I24: √ | J24: =IF(M24="是",K23,"") | K24: =_xlfn.WORKDAY.INTL(J24,L24,1,法定节假日!B25:B51) -> #VALUE! | P24: =NETWORKDAYS(N24,O24) -> 0 | S24: 未完成
D25: 平台永久授权申请 | J25: =IF(M25="是",K24,"") | K25: =_xlfn.WORKDAY.INTL(J25,L25,1,法定节假日!B26:B52) -> #VALUE! | P25: =NETWORKDAYS(N25,O25) -> 0 | S25: 未完成

Sheet 法定节假日
A1: 2023假日 | B1: 日期 | D1: 2024假日 | E1: 日期
A2: 元旦 | B2: 45290
B3: 45291
B4: 45292
A5: 春节 | B5: 45332
B6: 45333
B7: 45334
B8: 45335
B9: 45336
B10: 45337
B11: 45338
B12: 45339
A13: 清明节 | B13: 45386
B14: 45387
B15: 45388
A16: 劳动节 | B16: 45413
B17: 45414
B18: 45415
B19: 45416
B20: 45417
A21: 端午节 | B21: 45451
B22: 45452
B23: 45453
A24: 中秋节 | B24: 45550
B25: 45551
B26: 45552
A27: 国庆 | B27: 45566
B28: 45567
B29: 45568
B30: 45569
B31: 45570
B32: 45571
B33: 45572
