Workbook

Sheet 里程碑计划
A2: 时间 | B2: 46266 | F2: 45170 | J2: 45200 | O2: 45231 | S2: 45261 | W2: 45292 | AB2: 45323
B3: 1 | C3: =B3+7 | D3: =C3+7 | E3: =D3+7 | F3: 4 | G3: =F3+7 | H3: =G3+7 | I3: =H3+7 | J3: 2 | K3: =J3+7 | L3: =K3+7 | M3: =L3+7 | N3: =M3+7 | O3: 6 | P3: =O3+7 | Q3: =P3+7 | R3: =Q3+7 | S3: 4 | T3: =S3+7 | U3: =T3+7 | V3: =U3+7 | W3: 1 | X3: =W3+7 | Y3: =X3+7 | Z3: =Y3+7 | AA3: =Z3+7 | AB3: 5 | AC3: =AB3+7 | AD3: =AC3+7 | AE3: =AD3+7
A5: 实施
A6: 开发
A7: 用户&IT
A9: 里程碑节点说明
A10: 序号 | B10: 里程碑 | E10: 开始时间 | G10: 结束时间 | I10: 天数
A11: 1 | B11: 项目启动会 | E11: =主计划!N15 | G11: =主计划!O15 | I11: =NETWORKDAYS(E11,G11,法定节假日!B2:B34)
A12: 2 | B12: 蓝图评审 | E12: =主计划!N28 | G12: =主计划!O28 | I12: =NETWORKDAYS(E12,G12,法定节假日!B2:B34)
A13: 3 | B13: 详设评审 | E13: =主计划!N33 | G13: =主计划!O33 | I13: =NETWORKDAYS(E13,G13,法定节假日!E2:E34)
A14: 4 | B14: UAT功能交付确认 | E14: =主计划!N61 | G14: =主计划!O61 | I14: =NETWORKDAYS(E14,G14,法定节假日!E2:E34)
A15: 5 | B15: 系统上线验收 | E15: =主计划!N83 | G15: =主计划!O83 | I15: =NETWORKDAYS(E15,G15,法定节假日!E2:E34)
A16: 6 | B16: 系统竣工验收 | E16: =主计划!N91 | G16: =主计划!O91 | I16: =NETWORKDAYS(E16,G16,法定节假日!E2:E34)

Sheet 主计划
A1: 一级流程 （阶段） | B1: 二级流程 （场景） | C1: 三级流程 （任务） | D1: 任务名称 | E1: 后置 | F1: 前置 | G1: 进度 | I1: 里程碑 | J1: 乙方 评审 | K1: 甲方 评审 | L1: PMO | M1: 工作周 | N1: 计划时间 | P1: 工作日 | Q1: 是否与上个任务为前后置关系 | R1: 执行人 | T1: 关键交付物 | U1: 2026年8月 | AJ1: 2026年9月 | BN1: 2026年10月 | CS1: 2026年11月 | DW1: 2026年12月 | FB1: 2027年1月 | GG1: 2027年2月 | HI1: 2027年3月 | IN1: 2027年4月 | JR1: 2027年5月 | KW1: 2027年6月 | MA1: 2027年7月 | NF1: 2027年8月 | OK1: 2027年9月 | PO1: 2027年10月 | QT1: 2027年11月 | RX1: 2027年12月
G2: 状态 | H2: 进度备注 | N2: 计划开始 | O2: 计划结束 | P2: 计划天数 | R2: 主责 | S2: 协助或支持 | U2: 46251 | V2: 46252 | W2: 46253 | X2: 46254 | Y2: 46255 | Z2: 46256 | AA2: 46257 | AB2: 46258 | AC2: 46259 | AD2: 46260 | AE2: 46261 | AF2: 46262 | AG2: 46263 | AH2: 46264 | AI2: 46265 | AJ2: 46266 | AK2: 46267 | AL2: 46268 | AM2: 46269 | AN2: 46270 | AO2: 46271 | AP2: 46272 | AQ2: 46273 | AR2: 46274 | AS2: 46275 | AT2: 46276 | AU2: 46277 | AV2: 46278 | AW2: 46279 | AX2: 46280 | AY2: 46281 | AZ2: 46282 | BA2: 46283 | BB2: 46284 | BC2: 46285 | BD2: 46286 | BE2: 46287 | BF2: 46288 | BG2: 46289 | BH2: 46290 | BI2: 46291 | BJ2: 46292 | BK2: 46293 | BL2: 46294 | BM2: 46295 | BN2: 46296 | BO2: 46297 | BP2: 46298 | BQ2: 46299 | BR2: 46300 | BS2: 46301 | BT2: 46302 | BU2: 46303 | BV2: 46304 | BW2: 46305 | BX2: 46306 | BY2: 46307 | BZ2: 46308 | CA2: 46309 | CB2: 46310 | CC2: 46311 | CD2: 46312 | CE2: 46313 | CF2: 46314 | CG2: 46315 | CH2: 46316 | CI2: 46317 | CJ2: 46318 | CK2: 46319 | CL2: 46320 | CM2: 46321 | CN2: 46322 | CO2: 46323 | CP2: 46324 | CQ2: 46325 | CR2: 46326 | CS2: 46327 | CT2: 46328 | CU2: 46329 | CV2: 46330 | CW2: 46331 | CX2: 46332 | CY2: 46333 | CZ2: 46334 | DA2: 46335 | DB2: 46336 | DC2: 46337 | DD2: 46338 | DE2: 46339 | DF2: 46340 | DG2: 46341 | DH2: 46342 | DI2: 46343 | DJ2: 46344 | DK2: 46345 | DL2: 46346 | DM2: 46347 | DN2: 46348 | DO2: 46349 | DP2: 46350 | DQ2: 46351 | DR2: 46352 | DS2: 46353 | DT2: 46354 | DU2: 46355 | DV2: 46356 | DW2: 46357 | DX2: 46358 | DY2: 46359 | DZ2: 46360 | EA2: 46361 | EB2: 46362 | EC2: 46363 | ED2: 46364 | EE2: 46365 | EF2: 46366 | EG2: 46367 | EH2: 46368 | EI2: 46369 | EJ2: 46370 | EK2: 46371 | EL2: 46372 | EM2: 46373 | EN2: 46374 | EO2: 46375 | EP2: 46376 | EQ2: 46377 | ER2: 46378 | ES2: 46379 | ET2: 46380 | EU2: 46381 | EV2: 46382 | EW2: 46383 | EX2: 46384 | EY2: 46385 | EZ2: 46386 | FA2: 46387 | FB2: 46388 | FC2: 46389 | FD2: 46390 | FE2: 46391 | FF2: 46392 | FG2: 46393 | FH2: 46394 | FI2: 46395 | FJ2: 46396 | FK2: 46397 | FL2: 46398 | FM2: 46399 | FN2: 46400 | FO2: 46401 | FP2: 46402 | FQ2: 46403 | FR2: 46404 | FS2: 46405 | FT2: 46406 | FU2: 46407 | FV2: 46408 | FW2: 46409 | FX2: 46410 | FY2: 46411 | FZ2: 46412 | GA2: 46413 | GB2: 46414 | GC2: 46415 | GD2: 46416 | GE2: 46417 | GF2: 46418 | GG2: 46419 | GH2: 46420 | GI2: 46421 | GJ2: 46422 | GK2: 46423 | GL2: 46424 | GM2: 46425 | GN2: 46426 | GO2: 46427 | GP2: 46428 | GQ2: 46429 | GR2: 46430 | GS2: 46431 | GT2: 46432 | GU2: 46433 | GV2: 46434 | GW2: 46435 | GX2: 46436 | GY2: 46437 | GZ2: 46438 | HA2: 46439 | HB2: 46440 | HC2: 46441 | HD2: 46442 | HE2: 46443 | HF2: 46444 | HG2: 46445 | HH2: 46446 | HI2: 46447 | HJ2: 46448 | HK2: 46449 | HL2: 46450 | HM2: 46451 | HN2: 46452 | HO2: 46453 | HP2: 46454 | HQ2: 46455 | HR2: 46456 | HS2: 46457 | HT2: 46458 | HU2: 46459 | HV2: 46460 | HW2: 46461 | HX2: 46462 | HY2: 46463 | HZ2: 46464 | IA2: 46465 | IB2: 46466 | IC2: 46467 | ID2: 46468 | IE2: 46469 | IF2: 46470 | IG2: 46471 | IH2: 46472 | II2: 46473 | IJ2: 46474 | IK2: 46475 | IL2: 46476 | IM2: 46477 | IN2: 46478 | IO2: 46479 | IP2: 46480 | IQ2: 46481 | IR2: 46482 | IS2: 46483 | IT2: 46484 | IU2: 46485 | IV2: 46486 | IW2: 46487 | IX2: 46488 | IY2: 46489 | IZ2: 46490 | JA2: 46491 | JB2: 46492 | JC2: 46493 | JD2: 46494 | JE2: 46495 | JF2: 46496 | JG2: 46497 | JH2: 46498 | JI2: 46499 | JJ2: 46500 | JK2: 46501 | JL2: 46502 | JM2: 46503 | JN2: 46504 | JO2: 46505 | JP2: 46506 | JQ2: 46507 | JR2: 46508 | JS2: 46509 | JT2: 46510 | JU2: 46511 | JV2: 46512 | JW2: 46513 | JX2: 46514 | JY2: 46515 | JZ2: 46516 | KA2: 46517 | KB2: 46518 | KC2: 46519 | KD2: 46520 | KE2: 46521 | KF2: 46522 | KG2: 46523 | KH2: 46524 | KI2: 46525 | KJ2: 46526 | KK2: 46527 | KL2: 46528 | KM2: 46529 | KN2: 46530 | KO2: 46531 | KP2: 46532 | KQ2: 46533 | KR2: 46534 | KS2: 46535 | KT2: 46536 | KU2: 46537 | KV2: 46538 | KW2: 46539 | KX2: 46540 | KY2: 46541 | KZ2: 46542 | LA2: 46543 | LB2: 46544 | LC2: 46545 | LD2: 46546 | LE2: 46547 | LF2: 46548 | LG2: 46549 | LH2: 46550 | LI2: 46551 | LJ2: 46552 | LK2: 46553 | LL2: 46554 | LM2: 46555 | LN2: 46556 | LO2: 46557 | LP2: 46558 | LQ2: 46559 | LR2: 46560 | LS2: 46561 | LT2: 46562 | LU2: 46563 | LV2: 46564 | LW2: 46565 | LX2: 46566 | LY2: 46567 | LZ2: 46568 | MA2: 46569 | MB2: 46570 | MC2: 46571 | MD2: 46572 | ME2: 46573 | MF2: 46574 | MG2: 46575 | MH2: 46576 | MI2: 46577 | MJ2: 46578 | MK2: 46579 | ML2: 46580 | MM2: 46581 | MN2: 46582 | MO2: 46583 | MP2: 46584 | MQ2: 46585 | MR2: 46586 | MS2: 46587 | MT2: 46588 | MU2: 46589 | MV2: 46590 | MW2: 46591 | MX2: 46592 | MY2: 46593 | MZ2: 46594 | NA2: 46595 | NB2: 46596 | NC2: 46597 | ND2: 46598 | NE2: 46599 | NF2: 46600 | NG2: 46601 | NH2: 46602 | NI2: 46603 | NJ2: 46604 | NK2: 46605 | NL2: 46606 | NM2: 46607 | NN2: 46608 | NO2: 46609 | NP2: 46610 | NQ2: 46611 | NR2: 46612 | NS2: 46613 | NT2: 46614 | NU2: 46615 | NV2: 46616 | NW2: 46617 | NX2: 46618 | NY2: 46619 | NZ2: 46620 | OA2: 46621 | OB2: 46622 | OC2: 46623 | OD2: 46624 | OE2: 46625 | OF2: 46626 | OG2: 46627 | OH2: 46628 | OI2: 46629 | OJ2: 46630 | OK2: 46631 | OL2: 46632 | OM2: 46633 | ON2: 46634 | OO2: 46635 | OP2: 46636 | OQ2: 46637 | OR2: 46638 | OS2: 46639 | OT2: 46640 | OU2: 46641 | OV2: 46642 | OW2: 46643 | OX2: 46644 | OY2: 46645 | OZ2: 46646 | PA2: 46647 | PB2: 46648 | PC2: 46649 | PD2: 46650 | PE2: 46651 | PF2: 46652 | PG2: 46653 | PH2: 46654 | PI2: 46655 | PJ2: 46656 | PK2: 46657 | PL2: 46658 | PM2: 46659 | PN2: 46660 | PO2: 46661 | PP2: 46662 | PQ2: 46663 | PR2: 46664 | PS2: 46665 | PT2: 46666 | PU2: 46667 | PV2: 46668 | PW2: 46669 | PX2: 46670 | PY2: 46671 | PZ2: 46672 | QA2: 46673 | QB2: 46674 | QC2: 46675 | QD2: 46676 | QE2: 46677 | QF2: 46678 | QG2: 46679 | QH2: 46680 | QI2: 46681 | QJ2: 46682 | QK2: 46683 | QL2: 46684 | QM2: 46685 | QN2: 46686 | QO2: 46687 | QP2: 46688 | QQ2: 46689 | QR2: 46690 | QS2: 46691 | QT2: 46692 | QU2: 46693 | QV2: 46694 | QW2: 46695 | QX2: 46696 | QY2: 46697 | QZ2: 46698 | RA2: 46699 | RB2: 46700 | RC2: 46701 | RD2: 46702 | RE2: 46703 | RF2: 46704 | RG2: 46705 | RH2: 46706 | RI2: 46707 | RJ2: 46708 | RK2: 46709 | RL2: 46710 | RM2: 46711 | RN2: 46712 | RO2: 46713 | RP2: 46714 | RQ2: 46715 | RR2: 46716 | RS2: 46717 | RT2: 46718 | RU2: 46719 | RV2: 46720 | RW2: 46721 | RX2: 46722 | RY2: 46723 | RZ2: 46724 | SA2: 46725 | SB2: 46726 | SC2: 46727 | SD2: 46728 | SE2: 46729 | SF2: 46730 | SG2: 46731 | SH2: 46732 | SI2: 46733 | SJ2: 46734 | SK2: 46735 | SL2: 46736 | SM2: 46737 | SN2: 46738 | SO2: 46739 | SP2: 46740 | SQ2: 46741 | SR2: 46742 | SS2: 46743 | ST2: 46744 | SU2: 46745 | SV2: 46746 | SW2: 46747 | SX2: 46748 | SY2: 46749 | SZ2: 46750 | TA2: 46751 | TB2: 46752
A3: 1 | D3: 项目准备 | G3: =IF(COUNTIF(G4:G15,"未完成")=COUNTA(G4:G15),"未完成",IF(COUNTIF(G4:G15,"已完成")=COUNTA(G4:G15),"已完成","进行中")) | N3: 46258 | O3: =_xlfn.WORKDAY.INTL(N3,P3-1,1,法定节假日!$B$2:$B$67) | P3: 10 | R3: 周年根
B4: 1.1 | D4: 内部启动 | G4: =项目准备WBS!S3 | M4: W0 | N4: =N3 | O4: =_xlfn.WORKDAY.INTL(N4,P4-1,1,法定节假日!$B$2:$B$67) | P4: 2 | R4: 陈本鸿
A5: ★ | C5: 1.1.1 | D5: 内部启动准备 | G5: =项目准备WBS!S4 | J5: √ | M5: W0 | N5: =N4 | O5: =_xlfn.WORKDAY.INTL(N5,P5-1,1,法定节假日!$B$2:$B$67) | P5: 1 | R5: 陈本鸿
A6: ★ | C6: 1.1.2 | D6: 内部启动会 | G6: =项目准备WBS!S11 | J6: √ | L6: √ | M6: W0 | N6: 46259 | O6: =_xlfn.WORKDAY.INTL(N6,P6-1,1,法定节假日!$B$2:$B$67) | P6: 1 | Q6: 是 | R6: 陈本鸿
B7: 1.2 | D7: 技术准备 | G7: =项目准备WBS!S14 | M7: W0 | N7: 46260 | O7: =_xlfn.WORKDAY.INTL(N7,P7-1,1,法定节假日!$B$2:$B$67) | P7: 3 | Q7: 是 | R7: 陈本鸿
A8: ★ | C8: 1.2.1 | D8: 用户业务流程获取 | G8: =项目准备WBS!S15 | M8: W0 | N8: =N7 | O8: =_xlfn.WORKDAY.INTL(N8,P8-1,1,法定节假日!$B$2:$B$67) | P8: 3 | R8: 陈本鸿
A9: ★ | C9: 1.2.2 | D9: 交付物V0.1准备 | G9: =项目准备WBS!S17 | J9: √ | L9: √ | M9: W0 | N9: =N8 | O9: =_xlfn.WORKDAY.INTL(N9,P9-1,1,法定节假日!$B$2:$B$67) | P9: 3 | R9: 陈本鸿 | T9: 《交付物V0.1》
A10: ★ | C10: 1.2.3 | D10: 调研问卷准备 | G10: =项目准备WBS!S20 | J10: √ | L10: √ | M10: W0 | N10: =N9 | O10: =_xlfn.WORKDAY.INTL(N10,P10-1,1,法定节假日!$B$2:$B$67) | P10: 3 | R10: 陈本鸿 | T10: 《调研问卷》
B11: 1.3 | D11: 项目启动 | G11: =项目准备WBS!S23 | M11: W1 | N11: 46265 | O11: =_xlfn.WORKDAY.INTL(N11,P11-1,1,法定节假日!$B$2:$B$67) | P11: 5 | Q11: 是 | R11: 周年根
A12: ★ | C12: 1.3.1 | D12: 组建客户团队 | G12: =项目准备WBS!S24 | K12: √ | M12: W1 | N12: =N11 | O12: =_xlfn.WORKDAY.INTL(N12,P12-1,1,法定节假日!$B$2:$B$67) | P12: 2 | R12: 陈本鸿 | T12: 《项目章程》
A13: ★ | C13: 1.3.2 | D13: 客户方准备办公环境 | G13: =项目准备WBS!S26 | M13: W1 | N13: =N12 | O13: =_xlfn.WORKDAY.INTL(N13,P13-1,1,法定节假日!$B$2:$B$67) | P13: 2 | R13: 陈本鸿
A14: ★ | C14: 1.3.3 | D14: 项目管理规划 | G14: =项目准备WBS!S28 | K14: √ | L14: √ | M14: W1 | N14: 46267 | O14: =_xlfn.WORKDAY.INTL(N14,P14-1,1,法定节假日!$B$2:$B$67) | P14: 3 | R14: 陈本鸿 | T14: 《项目管理方案》什么东西？谁提供
A15: ★ | C15: 1.3.4 | D15: 召开启动会 | G15: =项目准备WBS!S30 | I15: √ | J15: √ | K15: √ | L15: √ | M15: W1 | N15: 46267 | O15: =_xlfn.WORKDAY.INTL(N15,P15-1,1,法定节假日!$B$2:$B$67) | P15: 3 | R15: 周年根 | T15: 《项目启动会PPT》
A16: 2 | D16: 需求分析 | G16: =IF(COUNTIF(G17:G43,"未完成")=COUNTA(G17:G43),"未完成",IF(COUNTIF(G17:G43,"已完成")=COUNTA(G17:G43),"已完成","进行中")) | M16: W1-W26 | N16: 46266 | O16: =_xlfn.WORKDAY.INTL(N16,P16-1,1,法定节假日!$B$2:$B$67) | P16: 113 | R16: 周年根
B17: 2.1 | D17: 业务调研与分析 | G17: =需求分析WBS!S3 | M17: W1-W13 | N17: =N16 | O17: =_xlfn.WORKDAY.INTL(N17,P17-1,1,法定节假日!$B$2:$B$67) | P17: 59 | R17: 陈本鸿
A18: ★ | C18: 2.1.1 | D18: 调研资料准备 | F18: 1.2.3 | G18: =需求分析WBS!S4 | M18: W1-W2 | N18: =N17 | O18: =_xlfn.WORKDAY.INTL(N18,P18-1,1,法定节假日!$B$2:$B$67) | P18: 9 | R18: 陈本鸿
A19: ★ | C19: 2.1.2 | D19: DP模块-业务调研与模拟分析 | F19: 1.2.1 | G19: =需求分析WBS!S7 | M19: W1-W5 | N19: =N17 | O19: =_xlfn.WORKDAY.INTL(N19,P19-1,1,法定节假日!$B$2:$B$67) | P19: 21 | R19: 文叶 | T19: 《调研纪要》-DP模块
C20: 2.1.3 | D20: APS模块-业务调研与模拟分析 | G20: =需求分析WBS!S13 | M20: W1-W9 | N20: =N18 | O20: =_xlfn.WORKDAY.INTL(N20,P20-1,1,法定节假日!$B$2:$B$67) | P20: 38 | R20: AP王旭东、AS林寒欣 | T20: 《调研纪要》-APS模块
C21: 2.1.4 | D21: IP模块-业务调研与模拟分析 | G21: =需求分析WBS!S19 | M21: W10-W13 | N21: 46328 | O21: =_xlfn.WORKDAY.INTL(N21,P21-1,1,法定节假日!$B$2:$B$67) | P21: 21 | R21: 宋沛霖 | T21: 《调研纪要》-IP模块
A22: ★ | C22: 2.1.5 | D22: 调研分析报告制定与评审 | G22: =需求分析WBS!S25 | J22: √ | K22: √ | L22: √ | N22: =IF(Q22="是",O21,"") | O22: =_xlfn.WORKDAY.INTL(N22,P22-1,1,法定节假日!$B$2:$B$67) | P22: 1 | Q22: 是 | R22: 陈本鸿 | T22: 《调研分析报告》
B23: 2.2 | D23: 系统蓝图设计 | G23: =需求分析WBS!S30 | M23: W1-W13 | N23: =N17 | O23: =_xlfn.WORKDAY.INTL(N23,P23-1,1,法定节假日!$B$2:$B$67) | P23: 59 | Q23: 是 | R23: 陈本鸿
A24: ★ | C24: 2.2.1 | D24: 需求确认与应答 | G24: =需求分析WBS!S31 | L24: √ | M24: W1-W5 | N24: =N23 | O24: =_xlfn.WORKDAY.INTL(N24,P24-1,1,法定节假日!$B$2:$B$67) | P24: 21 | R24: 陈本鸿 | T24: 《需求清单》《URS需求应答》
A25: ★ | C25: 2.2.2 | D25: DP模块-蓝图设计报告制定 | G25: =需求分析WBS!S34 | L25: √ | M25: W1-W5 | N25: =N24 | O25: =_xlfn.WORKDAY.INTL(N25,P25-1,1,法定节假日!$B$2:$B$67) | P25: 21 | R25: 文叶 | T25: 《蓝图设计报告》
C26: 2.2.3 | D26: APS模块-蓝图设计报告制定 | G26: =需求分析WBS!S39 | M26: W1-W9 | N26: =N24 | O26: =_xlfn.WORKDAY.INTL(N26,P26-1,1,法定节假日!$B$2:$B$67) | P26: 38 | R26: AP王旭东、AS林寒欣 | T26: 《蓝图设计报告》
C27: 2.2.4 | D27: IP模块-蓝图设计报告制定 | G27: =需求分析WBS!S44 | M27: W10-W13 | N27: 46328 | O27: =_xlfn.WORKDAY.INTL(N27,P27-1,1,法定节假日!$B$2:$B$67) | P27: 21 | Q27: 是 | R27: 宋沛霖 | T27: 《蓝图设计报告》
A28: ★ | C28: 2.2.5 | D28: 蓝图评审与签字确认 | G28: =需求分析WBS!S49 | I28: √ | J28: √ | K28: √ | L28: √ | N28: =IF(Q28="是",O27,"") | O28: =_xlfn.WORKDAY.INTL(N28,P28-1,1,法定节假日!$B$2:$B$67) | P28: 1 | Q28: 是 | R28: 周年根 | T28: 《蓝图验收确认单》
B29: 2.3 | D29: 系统详细设计 | G29: =需求分析WBS!S52 | M29: W12-W25 | N29: 46342 | O29: =_xlfn.WORKDAY.INTL(N29,P29-1,1,法定节假日!$B$2:$B$67) | P29: 60 | Q29: 是 | R29: 陈本鸿
A30: ★ | C30: 2.3.1 | D30: DP模块-系统详设文档制定 | G30: =需求分析WBS!S53 | M30: W12-W15 | N30: =N29 | O30: =_xlfn.WORKDAY.INTL(N30,P30-1,1,法定节假日!$B$2:$B$67) | P30: 20 | R30: 文叶
C31: 2.3.2 | D31: APS模块-系统详设文档制定 | G31: =需求分析WBS!S58 | M31: W12-W20 | N31: =N30 | O31: =_xlfn.WORKDAY.INTL(N31,P31-1,1,法定节假日!$B$2:$B$67) | P31: 42 | R31: AP王旭东、AS林寒欣
C32: 2.3.3 | D32: IP模块-系统详设文档制定 | G32: =需求分析WBS!S63 | M32: W21-W25 | N32: 46405 | O32: =_xlfn.WORKDAY.INTL(N32,P32-1,1,法定节假日!$B$2:$B$67) | P32: 18 | R32: 宋沛霖
A33: ★ | C33: 2.3.4 | D33: 系统详设评审与签字确认 | G33: =需求分析WBS!S68 | J33: √ | K33: √ | L33: √ | N33: 46437 | O33: =_xlfn.WORKDAY.INTL(N33,P33-1,1,法定节假日!$B$2:$B$67) | P33: 1 | Q33: 是 | R33: 周年根 | T33: 《系统详细设计文档》
B34: 2.4 | D34: 输入数据处理与收集 | G34: =需求分析WBS!S71 | M34: W4-W13 | N34: 46286 | O34: =_xlfn.WORKDAY.INTL(N34,P34-1,1,法定节假日!$B$2:$B$67) | P34: 45 | Q34: 是 | R34: 陈本鸿
A35: ★ | C35: 2.4.1 | D35: 数据收集模板制定与评审 | G35: =需求分析WBS!S72 | K35: √ | M35: W4-W13 | N35: =N34 | O35: =_xlfn.WORKDAY.INTL(N35,P35-1,1,法定节假日!$B$2:$B$67) | P35: 45 | R35: 陈本鸿 | T35: 《数据收集模板》
A36: ★ | C36: 2.4.2 | D36: 少量产品数据收集与验证 | G36: =需求分析WBS!S76 | M36: W4-W13 | N36: =N35 | O36: =_xlfn.WORKDAY.INTL(N36,P36-1,1,法定节假日!$B$2:$B$67) | P36: 45 | R36: 宋沛霖
A37: ★ | C37: 2.4.3 | D37: 接口接入数据管理方案制定 | G37: =需求分析WBS!S80 | J37: √ | K37: √ | L37: √ | M37: W4-W13 | N37: =N36 | O37: =_xlfn.WORKDAY.INTL(N37,P37-1,1,法定节假日!$B$2:$B$67) | P37: 45 | R37: 宋沛霖 | T37: 《接口接入数据管理方案》
A38: ★ | C38: 2.4.4 | D38: 对接系统数据处理与验证 | G38: =需求分析WBS!S84 | M38: W4-W13 | N38: =N37 | O38: =_xlfn.WORKDAY.INTL(N38,P38-1,1,法定节假日!$B$2:$B$67) | P38: 45 | R38: 宋沛霖
A39: ★ | C39: 2.4.5 | D39: 全量产品数据与规则收集 | E39: 4.1.2 | G39: =需求分析WBS!S86 | M39: W4-W13 | N39: =N38 | O39: =_xlfn.WORKDAY.INTL(N39,P39-1,1,法定节假日!$B$2:$B$67) | P39: 45 | R39: 宋沛霖 | T39: 《全量数据收集表》
B40: 2.5 | D40: 运行环境准备 | G40: =需求分析WBS!S89 | M40: W25-W26 | N40: 46433 | O40: =_xlfn.WORKDAY.INTL(N40,P40-1,1,法定节假日!$B$2:$B$67) | P40: 10 | R40: 陈本鸿
...

Sheet 项目准备WBS
A1: 二级流程 （场景） | B1: 三级流程 （任务） | C1: 任务名称 | D1: WBS | E1: 说明 | F1: 里程碑 | G1: 乙方 评审 | H1: 甲方 评审 | I1: PMO | J1: 计划时间 | L1: 工作日 | M1: 是否与上个任务为前后置关系 | N1: 实际时间 | P1: 工作日 | Q1: 执行人 | S1: 进度 | U1: 交付物
J2: 计划开始 | K2: 计划结束 | L2: 计划天数 | N2: 实际开始 | O2: 实际完成 | P2: 实际天数 | Q2: 主责 | R2: 协助或支持 | S2: 状态 | T2: 进度备注
A3: 1.1 | C3: 内部启动 | J3: =主计划!N4 | K3: =主计划!O4 | L3: =主计划!P4 | N3: =MIN(N4:N13) | O3: =MAX(O4:O13) | P3: =NETWORKDAYS(N3,O3) | Q3: 陈本鸿 | S3: =IF(COUNTIF(S4:S13,"未完成")=COUNTA(S4:S13),"未完成",IF(COUNTIF(S4:S13,"已完成")=COUNTA(S4:S13),"已完成","进行中"))
B4: 1.1.1 | C4: 内部启动准备 | J4: =主计划!N5 | K4: =主计划!O5 | L4: =主计划!P5 | N4: =MIN(N5:N10) | O4: =MAX(O5:O10) | P4: =NETWORKDAYS(N4,O4) | Q4: 陈本鸿 | S4: =IF(COUNTIF(S5:S10,"未完成")=COUNTA(S5:S10),"未完成",IF(COUNTIF(S5:S10,"已完成")=COUNTA(S5:S10),"已完成","进行中"))
D5: 选择团队成员 | J5: =J4 | K5: =_xlfn.WORKDAY.INTL(J5,L5-1,1,法定节假日!$B$2:$B$67) | L5: 1 | P5: =NETWORKDAYS(N5,O5) | S5: 未完成
D6: 组织售前交接会 | I6: √ | J6: =J4 | K6: =_xlfn.WORKDAY.INTL(J6,L6-1,1,法定节假日!$B$2:$B$67) | L6: 1 | P6: =NETWORKDAYS(N6,O6) | S6: 未完成
D7: 制度模板裁剪 | I7: √ | J7: =J4 | K7: =_xlfn.WORKDAY.INTL(J7,L7-1,1,法定节假日!$B$2:$B$67) | L7: 1 | P7: =NETWORKDAYS(N7,O7) | S7: 未完成
D8: 项目基线制定 | J8: =J4 | K8: =_xlfn.WORKDAY.INTL(J8,L8-1,1,法定节假日!$B$2:$B$67) | L8: 1 | P8: =NETWORKDAYS(N8,O8) | S8: 未完成
D9: 项目基线评审 | G9: √ | I9: √ | J9: =J4 | K9: =_xlfn.WORKDAY.INTL(J9,L9-1,1,法定节假日!$B$2:$B$67) | L9: 1 | P9: =NETWORKDAYS(N9,O9) | S9: 未完成
D10: CRM建项 | I10: √ | J10: =J4 | K10: =_xlfn.WORKDAY.INTL(J10,L10-1,1,法定节假日!$B$2:$B$67) | L10: 1 | P10: =NETWORKDAYS(N10,O10) | S10: 未完成
B11: 1.1.2 | C11: 内部启动会 | J11: =主计划!N6 | K11: =主计划!O6 | L11: =主计划!P6 | N11: =MIN(N12:N13) | O11: =MAX(O12:O13) | P11: =NETWORKDAYS(N11,O11) | Q11: 陈本鸿 | S11: =IF(COUNTIF(S12:S13,"未完成")=COUNTA(S12:S13),"未完成",IF(COUNTIF(S12:S13,"已完成")=COUNTA(S12:S13),"已完成","进行中"))
D12: 内部启动材料准备 | I12: √ | J12: =J11 | K12: =_xlfn.WORKDAY.INTL(J12,L12-1,1,法定节假日!$B$2:$B$67) | L12: 1 | P12: =NETWORKDAYS(N12,O12) | S12: 未完成
D13: 组织内部启动会 | G13: √ | I13: √ | J13: =J11 | K13: =_xlfn.WORKDAY.INTL(J13,L13-1,1,法定节假日!$B$2:$B$67) | L13: 1 | P13: =NETWORKDAYS(N13,O13) | S13: 未完成
A14: 1.2 | C14: 技术准备 | J14: =主计划!N7 | K14: =主计划!O7 | L14: =主计划!P7 | N14: =MIN(N15:N22) | O14: =MAX(O15:O22) | P14: =NETWORKDAYS(N14,O14) | Q14: 陈本鸿 | S14: =IF(COUNTIF(S15:S22,"未完成")=COUNTA(S15:S22),"未完成",IF(COUNTIF(S15:S22,"已完成")=COUNTA(S15:S22),"已完成","进行中"))
B15: 1.2.1 | C15: 用户业务流程获取 | J15: =主计划!N8 | K15: =主计划!O8 | L15: =主计划!P8 | N15: =MIN(N16:N16) | O15: =MAX(O16:O16) | P15: =NETWORKDAYS(N15,O15) | Q15: 陈本鸿 | S15: =IF(COUNTIF(S16:S16,"未完成")=COUNTA(S16:S16),"未完成",IF(COUNTIF(S16:S16,"已完成")=COUNTA(S16:S16),"已完成","进行中"))
D16: 用户业务流程获取 | J16: =J15 | K16: =_xlfn.WORKDAY.INTL(J16,L16-1,1,法定节假日!$B$2:$B$67) | L16: =L15 | P16: =NETWORKDAYS(N16,O16) | S16: 未完成
B17: 1.2.2 | C17: 交付物V0.1准备 | J17: =主计划!N9 | K17: =主计划!O9 | L17: =主计划!P9 | N17: =MIN(N18:N19) | O17: =MAX(O18:O19) | P17: =NETWORKDAYS(N17,O17) | Q17: 陈本鸿 | S17: =IF(COUNTIF(S18:S19,"未完成")=COUNTA(S18:S19),"未完成",IF(COUNTIF(S18:S19,"已完成")=COUNTA(S18:S19),"已完成","进行中"))
D18: 交付物V0.1制定 | J18: =J17 | K18: =_xlfn.WORKDAY.INTL(J18,L18-1,1,法定节假日!$B$2:$B$67) | L18: 2 | P18: =NETWORKDAYS(N18,O18) | S18: 未完成
D19: 技术顾问评审 | G19: √ | I19: √ | J19: =_xlfn.WORKDAY.INTL(K18,1,1,法定节假日!$B$2:$B$67) | K19: =_xlfn.WORKDAY.INTL(J19,L19-1,1,法定节假日!$B$2:$B$67) | L19: =L17-SUM(L18:L18) | P19: =NETWORKDAYS(N19,O19) | S19: 未完成
B20: 1.2.3 | C20: 调研问卷准备 | J20: =主计划!N10 | K20: =主计划!O10 | L20: =主计划!P10 | N20: =MIN(N21:N22) | O20: =MAX(O21:O22) | P20: =NETWORKDAYS(N20,O20) | Q20: 陈本鸿 | S20: =IF(COUNTIF(S21:S22,"未完成")=COUNTA(S21:S22),"未完成",IF(COUNTIF(S21:S22,"已完成")=COUNTA(S21:S22),"已完成","进行中"))
D21: 调研问卷准备 | J21: =J20 | K21: =_xlfn.WORKDAY.INTL(J21,L21-1,1,法定节假日!$B$2:$B$67) | L21: 2 | P21: =NETWORKDAYS(N21,O21) | S21: 未完成
D22: 技术顾问评审 | G22: √ | I22: √ | J22: =_xlfn.WORKDAY.INTL(K21,1,1,法定节假日!$B$2:$B$67) | K22: =_xlfn.WORKDAY.INTL(J22,L22-1,1,法定节假日!$B$2:$B$67) | L22: =L20-SUM(L21:L21) | P22: =NETWORKDAYS(N22,O22) | S22: 未完成
A23: 1.3 | C23: 项目启动 | J23: =主计划!N11 | K23: =主计划!O11 | L23: =主计划!P11 | N23: =MIN(N24:N33) | O23: =MAX(O24:O33) | P23: =NETWORKDAYS(N23,O23) | Q23: 周年根 | S23: =IF(COUNTIF(S24:S33,"未完成")=COUNTA(S24:S33),"未完成",IF(COUNTIF(S24:S33,"已完成")=COUNTA(S24:S33),"已完成","进行中"))
B24: 1.3.1 | C24: 组建客户团队 | J24: =主计划!N12 | K24: =主计划!O12 | L24: =主计划!P12 | N24: =MIN(N25:N25) | O24: =MAX(O25:O25) | P24: =NETWORKDAYS(N24,O24) | Q24: 陈本鸿 | S24: =IF(COUNTIF(S25:S25,"未完成")=COUNTA(S25:S25),"未完成",IF(COUNTIF(S25:S25,"已完成")=COUNTA(S25:S25),"已完成","进行中"))
D25: 指导组建客户团队 | H25: √ | J25: =J24 | K25: =_xlfn.WORKDAY.INTL(J25,L25-1,1,法定节假日!$B$2:$B$67) | L25: =L24 | P25: =NETWORKDAYS(N25,O25) | S25: 未完成
B26: 1.3.2 | C26: 客户方准备办公环境 | J26: =主计划!N13 | K26: =主计划!O13 | L26: =主计划!P13 | N26: =MIN(N27:N27) | O26: =MAX(O27:O27) | P26: =NETWORKDAYS(N26,O26) | Q26: 陈本鸿 | S26: =IF(COUNTIF(S27:S27,"未完成")=COUNTA(S27:S27),"未完成",IF(COUNTIF(S27:S27,"已完成")=COUNTA(S27:S27),"已完成","进行中"))
D27: 客户办公环境准备 | J27: =J26 | K27: =_xlfn.WORKDAY.INTL(J27,L27-1,1,法定节假日!$B$2:$B$67) | L27: =L26 | P27: =NETWORKDAYS(N27,O27) | S27: 未完成
B28: 1.3.3 | C28: 项目管理规划 | J28: =主计划!N14 | K28: =主计划!O14 | L28: =主计划!P14 | N28: =MIN(N29:N29) | O28: =MAX(O29:O29) | P28: =NETWORKDAYS(N28,O28) | Q28: 陈本鸿 | S28: =IF(COUNTIF(S29:S29,"未完成")=COUNTA(S29:S29),"未完成",IF(COUNTIF(S29:S29,"已完成")=COUNTA(S29:S29),"已完成","进行中"))
D29: 项目管理方案确定 | H29: √ | I29: √ | J29: =J28 | K29: =_xlfn.WORKDAY.INTL(J29,L29-1,1,法定节假日!$B$2:$B$67) | L29: =L28 | P29: =NETWORKDAYS(N29,O29) | S29: 未完成
B30: 1.3.4 | C30: 召开启动会 | J30: =主计划!N15 | K30: =主计划!O15 | L30: =主计划!P15 | N30: =MIN(N31:N33) | O30: =MAX(O31:O33) | P30: =NETWORKDAYS(N30,O30) | Q30: 周年根 | S30: =IF(COUNTIF(S31:S33,"未完成")=COUNTA(S31:S33),"未完成",IF(COUNTIF(S31:S33,"已完成")=COUNTA(S31:S33),"已完成","进行中"))
D31: 启动会流程讨论 | J31: =J30 | K31: =_xlfn.WORKDAY.INTL(J31,L31-1,1,法定节假日!$B$2:$B$67) | L31: 1 | P31: =NETWORKDAYS(N31,O31) | S31: 未完成
D32: 启动会PPT制作与同行评审 | G32: √ | H32: √ | I32: √ | J32: =_xlfn.WORKDAY.INTL(K31,1,1,法定节假日!$B$2:$B$67) | K32: =_xlfn.WORKDAY.INTL(J32,L32-1,1,法定节假日!$B$2:$B$67) | L32: 1 | P32: =NETWORKDAYS(N32,O32) | S32: 未完成
D33: 召开启动会 | F33: √ | J33: =_xlfn.WORKDAY.INTL(K32,1,1,法定节假日!$B$2:$B$67) | K33: =_xlfn.WORKDAY.INTL(J33,L33-1,1,法定节假日!$B$2:$B$67) | L33: =L30-SUM(L31:L32) | P33: =NETWORKDAYS(N33,O33) | S33: 未完成
B37: 1、与主计划相同，每个阶段的WBS中，计划时间制定时，填写计划开始时间和工作日计划天数即可输出计划结束时间
B38: 2、二级任务实际开始时间和实际完成时间可通过编辑三四级任务完成时间识别出。
B39: 3、四级任务手动编辑实际开始时间和实际完成时间自动计算出实际工作天数
B40: 4、通过四级任务【状态】下拉框，选择状态为“未完成”、“进行中”和“已完成”，主计划中的任务状态会自动更新。
B41: 5、乱码没有关系，按照以上说明编辑乱码即可生成日期

Sheet 需求分析WBS
A1: 二级流程 （场景） | B1: 三级流程 （任务） | C1: 任务名称 | D1: WBS | E1: 说明 | F1: 里程碑 | G1: 乙方 评审 | H1: 甲方 评审 | I1: PMO 监控&评审点 | J1: 计划时间 | L1: 工作日 | M1: 是否与上个任务为前后置关系 | N1: 实际时间 | P1: 工作日 | Q1: 执行人 | S1: 进度 | U1: 交付物
J2: 计划开始 | K2: 计划结束 | L2: 计划天数 | N2: 实际开始 | O2: 实际完成 | P2: 实际天数 | Q2: 主责 | R2: 协助或支持 | S2: 状态 | T2: 进度备注
A3: 2.1 | C3: 业务调研与分析 | J3: =主计划!N17 | K3: =主计划!O17 | L3: =主计划!P17 | N3: =MIN(N4:N29) | O3: =MAX(O4:O29) | P3: =NETWORKDAYS(N3,O3) | Q3: 陈本鸿 | S3: =IF(COUNTIF(S4:S29,"未完成")=COUNTA(S4:S29),"未完成",IF(COUNTIF(S4:S29,"已完成")=COUNTA(S4:S29),"已完成","进行中"))
B4: 2.1.1 | C4: 调研资料准备 | J4: =主计划!N18 | K4: =主计划!O18 | L4: =主计划!P18 | N4: =MIN(N5:N6) | O4: =MAX(O5:O6) | P4: =NETWORKDAYS(N4,O4) | Q4: 陈本鸿 | S4: =IF(COUNTIF(S5:S6,"未完成")=COUNTA(S5:S6),"未完成",IF(COUNTIF(S5:S6,"已完成")=COUNTA(S5:S6),"已完成","进行中"))
D5: 调研问卷用户确认 | J5: =J4 | K5: =_xlfn.WORKDAY.INTL(J5,L5-1,1,法定节假日!$B$2:$B$67) | L5: 4 | P5: =NETWORKDAYS(N5,O5) | S5: 未完成
D6: 用户调研计划制定与评审 | J6: =_xlfn.WORKDAY.INTL(K5,1,1,法定节假日!$B$2:$B$67) | K6: =_xlfn.WORKDAY.INTL(J6,L6-1,1,法定节假日!$B$2:$B$67) | L6: =L4-SUM(L5:L5) | P6: =NETWORKDAYS(N6,O6) | S6: 未完成
B7: 2.1.2 | C7: DP模块-业务调研与模拟分析 | J7: =主计划!N19 | K7: =主计划!O19 | L7: =主计划!P19 | N7: =MIN(N8:N12) | O7: =MAX(O8:O12) | P7: =NETWORKDAYS(N7,O7) | Q7: 文叶 | S7: =IF(COUNTIF(S8:S12,"未完成")=COUNTA(S8:S12),"未完成",IF(COUNTIF(S8:S12,"已完成")=COUNTA(S8:S12),"已完成","进行中"))
D8: 对接埃森哲调研成果 | J8: =J7 | K8: =_xlfn.WORKDAY.INTL(J8,L8-1,1,法定节假日!$B$2:$B$67) | L8: 2 | P8: =NETWORKDAYS(N8,O8) | S8: 未完成
D9: 初版业务场景流程梳理 | J9: =_xlfn.WORKDAY.INTL(K8,1,1,法定节假日!$B$2:$B$67) | K9: =_xlfn.WORKDAY.INTL(J9,L9-1,1,法定节假日!$B$2:$B$67) | L9: 4 | P9: =NETWORKDAYS(N9,O9) | S9: 未完成
D10: 业务流程差异分析及讨论 | J10: =_xlfn.WORKDAY.INTL(K9,1,1,法定节假日!$B$2:$B$67) | K10: =_xlfn.WORKDAY.INTL(J10,L10-1,1,法定节假日!$B$2:$B$67) | L10: 5 | P10: =NETWORKDAYS(N10,O10) | S10: 未完成
D11: 业务优化策略确认 | J11: =_xlfn.WORKDAY.INTL(K10,1,1,法定节假日!$B$2:$B$67) | K11: =_xlfn.WORKDAY.INTL(J11,L11-1,1,法定节假日!$B$2:$B$67) | L11: 5 | P11: =NETWORKDAYS(N11,O11) | S11: 未完成
D12: 接口清单梳理与确认 | J12: =_xlfn.WORKDAY.INTL(K11,1,1,法定节假日!$B$2:$B$67) | K12: =_xlfn.WORKDAY.INTL(J12,L12-1,1,法定节假日!$B$2:$B$67) | L12: =L7-SUM(L8:L11) | P12: =NETWORKDAYS(N12,O12) | S12: 未完成
B13: 2.1.3 | C13: APS模块-业务调研与模拟分析 | J13: =主计划!N20 | K13: =主计划!O20 | L13: =主计划!P20 | N13: =MIN(N14:N18) | O13: =MAX(O14:O18) | P13: =NETWORKDAYS(N13,O13) | Q13: AP王旭东、AS林寒欣 | S13: =IF(COUNTIF(S14:S18,"未完成")=COUNTA(S14:S18),"未完成",IF(COUNTIF(S14:S18,"已完成")=COUNTA(S14:S18),"已完成","进行中"))
D14: 对接埃森哲调研成果 | J14: =J13 | K14: =_xlfn.WORKDAY.INTL(J14,L14-1,1,法定节假日!$B$2:$B$67) | L14: 4 | P14: =NETWORKDAYS(N14,O14) | S14: 未完成
D15: 初版业务场景流程梳理 | J15: =_xlfn.WORKDAY.INTL(K14,1,1,法定节假日!$B$2:$B$67) | K15: =_xlfn.WORKDAY.INTL(J15,L15-1,1,法定节假日!$B$2:$B$67) | L15: 8 | P15: =NETWORKDAYS(N15,O15) | S15: 未完成
D16: 业务流程差异分析及讨论 | J16: =_xlfn.WORKDAY.INTL(K15,1,1,法定节假日!$B$2:$B$67) | K16: =_xlfn.WORKDAY.INTL(J16,L16-1,1,法定节假日!$B$2:$B$67) | L16: 9 | P16: =NETWORKDAYS(N16,O16) | S16: 未完成
D17: 业务优化策略确认 | J17: =_xlfn.WORKDAY.INTL(K16,1,1,法定节假日!$B$2:$B$67) | K17: =_xlfn.WORKDAY.INTL(J17,L17-1,1,法定节假日!$B$2:$B$67) | L17: 9 | P17: =NETWORKDAYS(N17,O17) | S17: 未完成
D18: 接口清单梳理与确认 | J18: =_xlfn.WORKDAY.INTL(K17,1,1,法定节假日!$B$2:$B$67) | K18: =_xlfn.WORKDAY.INTL(J18,L18-1,1,法定节假日!$B$2:$B$67) | L18: =L13-SUM(L14:L17) | P18: =NETWORKDAYS(N18,O18) | S18: 未完成
B19: 2.1.4 | C19: IP模块-业务调研与模拟分析 | J19: =主计划!N21 | K19: =主计划!O21 | L19: =主计划!P21 | N19: =MIN(N20:N24) | O19: =MAX(O20:O24) | P19: =NETWORKDAYS(N19,O19) | Q19: 宋沛霖 | S19: =IF(COUNTIF(S20:S24,"未完成")=COUNTA(S20:S24),"未完成",IF(COUNTIF(S20:S24,"已完成")=COUNTA(S20:S24),"已完成","进行中"))
D20: 对接埃森哲调研成果 | J20: =J19 | K20: =_xlfn.WORKDAY.INTL(J20,L20-1,1,法定节假日!$B$2:$B$67) | L20: 2 | P20: =NETWORKDAYS(N20,O20) | S20: 未完成
D21: 初版业务场景流程梳理 | J21: =_xlfn.WORKDAY.INTL(K20,1,1,法定节假日!$B$2:$B$67) | K21: =_xlfn.WORKDAY.INTL(J21,L21-1,1,法定节假日!$B$2:$B$67) | L21: 5 | P21: =NETWORKDAYS(N21,O21) | S21: 未完成
D22: 业务流程差异分析及讨论 | J22: =_xlfn.WORKDAY.INTL(K21,1,1,法定节假日!$B$2:$B$67) | K22: =_xlfn.WORKDAY.INTL(J22,L22-1,1,法定节假日!$B$2:$B$67) | L22: 5 | P22: =NETWORKDAYS(N22,O22) | S22: 未完成
D23: 业务优化策略确认 | J23: =_xlfn.WORKDAY.INTL(K22,1,1,法定节假日!$B$2:$B$67) | K23: =_xlfn.WORKDAY.INTL(J23,L23-1,1,法定节假日!$B$2:$B$67) | L23: 5 | P23: =NETWORKDAYS(N23,O23) | S23: 未完成
D24: 接口清单梳理与确认 | J24: =_xlfn.WORKDAY.INTL(K23,1,1,法定节假日!$B$2:$B$67) | K24: =_xlfn.WORKDAY.INTL(J24,L24-1,1,法定节假日!$B$2:$B$67) | L24: =L19-SUM(L20:L23) | P24: =NETWORKDAYS(N24,O24) | S24: 未完成
B25: 2.1.5 | C25: 调研分析报告制定与评审 | J25: =主计划!N22 | K25: =主计划!O22 | L25: =主计划!P22 | N25: =MIN(N26:N29) | O25: =MAX(O26:O29) | P25: =NETWORKDAYS(N25,O25) | Q25: 陈本鸿 | S25: =IF(COUNTIF(S26:S29,"未完成")=COUNTA(S26:S29),"未完成",IF(COUNTIF(S26:S29,"已完成")=COUNTA(S26:S29),"已完成","进行中"))
D26: 调研分析报告制定 | J26: =J25 | K26: =_xlfn.WORKDAY.INTL(J26,L26-1,1,法定节假日!$B$2:$B$67) | L26: 1 | P26: =NETWORKDAYS(N26,O26) | S26: 未完成
D27: 技术顾问评审确认 | J27: =J25 | K27: =_xlfn.WORKDAY.INTL(J27,L27-1,1,法定节假日!$B$2:$B$67) | L27: 1 | P27: =NETWORKDAYS(N27,O27) | S27: 未完成
D28: 关键用户评审确认 | G28: √ | H28: √ | I28: √ | J28: =J25 | K28: =_xlfn.WORKDAY.INTL(J28,L28-1,1,法定节假日!$B$2:$B$67) | L28: 1 | P28: =NETWORKDAYS(N28,O28) | S28: 未完成
D29: 谷斗内部评审确认 | H29: √ | J29: =J25 | K29: =_xlfn.WORKDAY.INTL(J29,L29-1,1,法定节假日!$B$2:$B$67) | L29: 1 | P29: =NETWORKDAYS(N29,O29) | S29: 未完成
A30: 2.2 | C30: 系统蓝图设计 | J30: =主计划!N23 | K30: =_xlfn.WORKDAY.INTL(J30,L30,1,法定节假日!$B$2:$B$67) | L30: =主计划!P23 | N30: =MIN(N31:N51) | O30: =MAX(O31:O51) | P30: =NETWORKDAYS(N30,O30) | Q30: 陈本鸿 | S30: =IF(COUNTIF(S31:S51,"未完成")=COUNTA(S31:S51),"未完成",IF(COUNTIF(S31:S51,"已完成")=COUNTA(S31:S51),"已完成","进行中"))
B31: 2.2.1 | C31: 需求确认与应答 | J31: =主计划!N24 | K31: =主计划!O24 | L31: =主计划!P24 | N31: =MIN(N32:N33) | O31: =MAX(O32:O33) | P31: =NETWORKDAYS(N31,O31) | Q31: 陈本鸿 | S31: =IF(COUNTIF(S32:S33,"未完成")=COUNTA(S32:S33),"未完成",IF(COUNTIF(S32:S33,"已完成")=COUNTA(S32:S33),"已完成","进行中"))
D32: 需求清单编写与确认 | G32: √ | H32: √ | I32: √ | J32: =J31 | K32: =_xlfn.WORKDAY.INTL(J32,L32-1,1,法定节假日!$B$2:$B$67) | L32: 11 | P32: =NETWORKDAYS(N32,O32) | S32: 未完成
D33: URS需求应答编写与确认 | G33: √ | H33: √ | I33: √ | J33: =_xlfn.WORKDAY.INTL(K32,1,1,法定节假日!$B$2:$B$67) | K33: =_xlfn.WORKDAY.INTL(J33,L33-1,1,法定节假日!$B$2:$B$67) | L33: =L31-SUM(L32:L32) | P33: =NETWORKDAYS(N33,O33) | S33: 未完成
B34: 2.2.2 | C34: DP模块-蓝图设计报告制定 | J34: =主计划!N25 | K34: =主计划!O25 | L34: =主计划!P25 | N34: =MIN(N35:N38) | O34: =MAX(O35:O38) | P34: =NETWORKDAYS(N34,O34) | Q34: 文叶 | S34: =IF(COUNTIF(S35:S38,"未完成")=COUNTA(S35:S38),"未完成",IF(COUNTIF(S35:S38,"已完成")=COUNTA(S35:S38),"已完成","进行中"))
D35: 蓝图设计报告制定 | J35: =J34 | K35: =_xlfn.WORKDAY.INTL(J35,L35-1,1,法定节假日!$B$2:$B$67) | L35: 9 | P35: =NETWORKDAYS(N35,O35) | S35: 未完成
D36: 技术顾问同行评审 | J36: =_xlfn.WORKDAY.INTL(K35,1,1,法定节假日!$B$2:$B$67) | K36: =_xlfn.WORKDAY.INTL(J36,L36-1,1,法定节假日!$B$2:$B$67) | L36: 4 | P36: =NETWORKDAYS(N36,O36) | S36: 未完成
D37: 关键用户同行评审 | J37: =_xlfn.WORKDAY.INTL(K36,1,1,法定节假日!$B$2:$B$67) | K37: =_xlfn.WORKDAY.INTL(J37,L37-1,1,法定节假日!$B$2:$B$67) | L37: 4 | P37: =NETWORKDAYS(N37,O37) | S37: 未完成
D38: 谷斗内部同行评审 | J38: =_xlfn.WORKDAY.INTL(K37,1,1,法定节假日!$B$2:$B$67) | K38: =_xlfn.WORKDAY.INTL(J38,L38-1,1,法定节假日!$B$2:$B$67) | L38: =L34-SUM(L35:L37) | P38: =NETWORKDAYS(N38,O38) | S38: 未完成
B39: 2.2.3 | C39: APS模块-蓝图设计报告制定 | J39: =主计划!N26 | K39: =主计划!O26 | L39: =主计划!P26 | N39: =MIN(N40:N43) | O39: =MAX(O40:O43) | P39: =NETWORKDAYS(N39,O39) | Q39: AP王旭东、AS林寒欣 | S39: =IF(COUNTIF(S40:S43,"未完成")=COUNTA(S40:S43),"未完成",IF(COUNTIF(S40:S43,"已完成")=COUNTA(S40:S43),"已完成","进行中"))
D40: 蓝图设计报告制定 | J40: =J39 | K40: =_xlfn.WORKDAY.INTL(J40,L40-1,1,法定节假日!$B$2:$B$67) | L40: 18 | P40: =NETWORKDAYS(N40,O40) | S40: 未完成
...

Sheet 系统实现WBS
A1: 二级流程 （场景） | B1: 三级流程 （任务） | C1: 任务名称 | D1: WBS | E1: 说明 | F1: 里程碑 | G1: 乙方 评审 | H1: 甲方 评审 | I1: PMO 监控&评审点 | J1: 计划时间 | L1: 工作日 | M1: 是否与上个任务为前后置关系 | N1: 实际时间 | P1: 工作日 | Q1: 执行人 | S1: 进度 | U1: 交付物
J2: 计划开始 | K2: 计划结束 | L2: 计划天数 | N2: 实际开始 | O2: 实际完成 | P2: 实际天数 | Q2: 主责 | R2: 协助或支持 | S2: 状态 | T2: 进度备注
A3: 3.1 | C3: 系统实现准备 | J3: =主计划!N45 | K3: =主计划!O45 | L3: =主计划!P45 | N3: =MIN(N4:N11) | O3: =MAX(O4:O11) | P3: =NETWORKDAYS(N3,O3) | Q3: 陈本鸿 | S3: =IF(COUNTIF(S4:S11,"未完成")=COUNTA(S4:S11),"未完成",IF(COUNTIF(S4:S11,"已完成")=COUNTA(S4:S11),"已完成","进行中"))
B4: 3.1.1 | C4: 开发设计及工时预估 | J4: =主计划!N46 | K4: =主计划!O46 | L4: =主计划!P46 | N4: =MIN(N5:N7) | O4: =MAX(O5:O7) | P4: =NETWORKDAYS(N4,O4) | Q4: 陈本鸿 | S4: =IF(COUNTIF(S5:S7,"未完成")=COUNTA(S5:S7),"未完成",IF(COUNTIF(S5:S7,"已完成")=COUNTA(S5:S7),"已完成","进行中"))
D5: 开发功能设计 | J5: =J4 | K5: =_xlfn.WORKDAY.INTL(J5,L5-1,1,法定节假日!$B$2:$B$67) | L5: 2 | P5: =NETWORKDAYS(N5,O5) | S5: 未完成
D6: 功能工时估算 | J6: =_xlfn.WORKDAY.INTL(K5,1,1,法定节假日!$B$2:$B$67) | K6: =_xlfn.WORKDAY.INTL(J6,L6-1,1,法定节假日!$B$2:$B$67) | L6: 2 | P6: =NETWORKDAYS(N6,O6) | S6: 未完成
D7: 开发设计评审 | G7: √ | I7: √ | J7: =_xlfn.WORKDAY.INTL(K6,1,1,法定节假日!$B$2:$B$67) | K7: =_xlfn.WORKDAY.INTL(J7,L7-1,1,法定节假日!$B$2:$B$67) | L7: =L4-SUM(L5:L6) | P7: =NETWORKDAYS(N7,O7) | S7: 未完成
B8: 3.1.2 | C8: 需求版本及发布计划确认 | J8: =主计划!N47 | K8: =主计划!O47 | L8: =主计划!P47 | N8: =MIN(N9:N11) | O8: =MAX(O9:O11) | P8: =NETWORKDAYS(N8,O8) | Q8: 陈本鸿 | S8: =IF(COUNTIF(S9:S11,"未完成")=COUNTA(S9:S11),"未完成",IF(COUNTIF(S9:S11,"已完成")=COUNTA(S9:S11),"已完成","进行中"))
D9: 需求版本制定与确认 | J9: =J8 | K9: =_xlfn.WORKDAY.INTL(J9,L9-1,1,法定节假日!$B$2:$B$67) | L9: 2 | P9: =NETWORKDAYS(N9,O9) | S9: 未完成
D10: 发布计划制定与确认 | G10: √ | H10: √ | I10: √ | J10: =_xlfn.WORKDAY.INTL(K9,1,1,法定节假日!$B$2:$B$67) | K10: =_xlfn.WORKDAY.INTL(J10,L10-1,1,法定节假日!$B$2:$B$67) | L10: 2 | P10: =NETWORKDAYS(N10,O10) | S10: 未完成
D11: 禅道需求和任务创建 | I11: √ | J11: =_xlfn.WORKDAY.INTL(K10,1,1,法定节假日!$B$2:$B$67) | K11: =_xlfn.WORKDAY.INTL(J11,L11-1,1,法定节假日!$B$2:$B$67) | L11: =L8-SUM(L9:L10) | P11: =NETWORKDAYS(N11,O11) | S11: 未完成
A12: 3.2 | C12: 版本开发与用户测试 | J12: =主计划!N48 | K12: =主计划!O48 | L12: =主计划!P48 | N12: =MIN(N13:N24) | O12: =MAX(O13:O24) | P12: =NETWORKDAYS(N12,O12) | Q12: 陈本鸿 | S12: =IF(COUNTIF(S13:S24,"未完成")=COUNTA(S13:S24),"未完成",IF(COUNTIF(S13:S24,"已完成")=COUNTA(S13:S24),"已完成","进行中"))
B13: 3.2.1 | C13: 开发测试数据准备 | J13: =主计划!N49 | K13: =主计划!O49 | L13: =主计划!P49 | N13: =MIN(N14:N16) | O13: =MAX(O14:O16) | P13: =NETWORKDAYS(N13,O13) | Q13: 宋沛霖 | S13: =IF(COUNTIF(S14:S16,"未完成")=COUNTA(S14:S16),"未完成",IF(COUNTIF(S14:S16,"已完成")=COUNTA(S14:S16),"已完成","进行中"))
D14: 测试用例制定与确认 | J14: =J13 | K14: =_xlfn.WORKDAY.INTL(J14,L14-1,1,法定节假日!$B$2:$B$67) | L14: 2 | P14: =NETWORKDAYS(N14,O14) | S14: 未完成
D15: 测试数据准备与确认 | J15: =_xlfn.WORKDAY.INTL(K14,1,1,法定节假日!$B$2:$B$67) | K15: =_xlfn.WORKDAY.INTL(J15,L15-1,1,法定节假日!$B$2:$B$67) | L15: 2 | P15: =NETWORKDAYS(N15,O15) | S15: 未完成
D16: 接口postman联调 | J16: =_xlfn.WORKDAY.INTL(K15,1,1,法定节假日!$B$2:$B$67) | K16: =_xlfn.WORKDAY.INTL(J16,L16-1,1,法定节假日!$B$2:$B$67) | L16: =L13-SUM(L14:L15) | P16: =NETWORKDAYS(N16,O16) | S16: 未完成
B17: 3.2.2 | C17: 开发实现与测试确认 | J17: =主计划!N50 | K17: =主计划!O50 | L17: =主计划!P50 | N17: =MIN(N18:N18) | O17: =MAX(O18:O18) | P17: =NETWORKDAYS(N17,O17) | Q17: 陈本鸿 | S17: =IF(COUNTIF(S18:S18,"未完成")=COUNTA(S18:S18),"未完成",IF(COUNTIF(S18:S18,"已完成")=COUNTA(S18:S18),"已完成","进行中"))
D18: 开发实现与测试确认 | J18: =J17 | K18: =_xlfn.WORKDAY.INTL(J18,L18-1,1,法定节假日!$B$2:$B$67) | L18: =L17 | P18: =NETWORKDAYS(N18,O18) | S18: 未完成
B19: 3.2.3 | C19: 顾问单元测试与确认 | J19: =主计划!N53 | K19: =主计划!O53 | L19: =主计划!P53 | N19: =MIN(N20:N20) | O19: =MAX(O20:O20) | P19: =NETWORKDAYS(N19,O19) | Q19: 陈本鸿 | S19: =IF(COUNTIF(S20:S20,"未完成")=COUNTA(S20:S20),"未完成",IF(COUNTIF(S20:S20,"已完成")=COUNTA(S20:S20),"已完成","进行中"))
D20: 顾问单元测试与确认 | J20: =J19 | K20: =_xlfn.WORKDAY.INTL(J20,L20-1,1,法定节假日!$B$2:$B$67) | L20: =L19 | P20: =NETWORKDAYS(N20,O20) | S20: 未完成
B21: 3.2.4 | C21: 用户单元测试与确认 | J21: =主计划!N54 | K21: =主计划!O54 | L21: =主计划!P54 | N21: =MIN(N22:N24) | O21: =MAX(O22:O24) | P21: =NETWORKDAYS(N21,O21) | Q21: 陈本鸿 | S21: =IF(COUNTIF(S22:S24,"未完成")=COUNTA(S22:S24),"未完成",IF(COUNTIF(S22:S24,"已完成")=COUNTA(S22:S24),"已完成","进行中"))
D22: 功能部署与配置 | J22: =J21 | K22: =_xlfn.WORKDAY.INTL(J22,L22-1,1,法定节假日!$B$2:$B$67) | L22: 9 | P22: =NETWORKDAYS(N22,O22) | S22: 未完成
D23: 组织用户培训与确认 | J23: =_xlfn.WORKDAY.INTL(K22,1,1,法定节假日!$B$2:$B$67) | K23: =_xlfn.WORKDAY.INTL(J23,L23-1,1,法定节假日!$B$2:$B$67) | L23: 5 | P23: =NETWORKDAYS(N23,O23) | S23: 未完成
D24: 用户单元测试与确认 | J24: =_xlfn.WORKDAY.INTL(K23,1,1,法定节假日!$B$2:$B$67) | K24: =_xlfn.WORKDAY.INTL(J24,L24-1,1,法定节假日!$B$2:$B$67) | L24: =L21-SUM(L22:L23) | P24: =NETWORKDAYS(N24,O24) | S24: 未完成
A25: 3.3 | C25: 用户集成测试 | J25: =主计划!N55 | K25: =主计划!O55 | L25: =主计划!P55 | N25: =MIN(N26:N43) | O25: =MAX(O26:O43) | P25: =NETWORKDAYS(N25,O25) | Q25: 陈本鸿 | S25: =IF(COUNTIF(S26:S43,"未完成")=COUNTA(S26:S43),"未完成",IF(COUNTIF(S26:S43,"已完成")=COUNTA(S26:S43),"已完成","进行中"))
B26: 3.3.1 | C26: 关键用户培训考核 | J26: =主计划!N56 | K26: =主计划!O56 | L26: =主计划!P56 | N26: =MIN(N27:N28) | O26: =MAX(O27:O28) | P26: =NETWORKDAYS(N26,O26) | Q26: 陈本鸿 | S26: =IF(COUNTIF(S27:S28,"未完成")=COUNTA(S27:S28),"未完成",IF(COUNTIF(S27:S28,"已完成")=COUNTA(S27:S28),"已完成","进行中"))
D27: 关键用户培训准备 | J27: =J26 | K27: =_xlfn.WORKDAY.INTL(J27,L27-1,1,法定节假日!$B$2:$B$67) | L27: 1 | P27: =NETWORKDAYS(N27,O27) | S27: 未完成
D28: 关键用户培训与考核 | J28: =_xlfn.WORKDAY.INTL(K27,1,1,法定节假日!$B$2:$B$67) | K28: =_xlfn.WORKDAY.INTL(J28,L28-1,1,法定节假日!$B$2:$B$67) | L28: =L26-SUM(L27:L27) | P28: =NETWORKDAYS(N28,O28) | S28: 未完成
B29: 3.3.2 | C29: 业务场景拉通测试 | J29: =主计划!N57 | K29: =主计划!O57 | L29: =主计划!P57 | N29: =MIN(N30:N34) | O29: =MAX(O30:O34) | P29: =NETWORKDAYS(N29,O29) | Q29: 陈本鸿 | S29: =IF(COUNTIF(S30:S34,"未完成")=COUNTA(S30:S34),"未完成",IF(COUNTIF(S30:S34,"已完成")=COUNTA(S30:S34),"已完成","进行中"))
D30: 场景测试计划制定与确认 | J30: =J29 | K30: =_xlfn.WORKDAY.INTL(J30,L30-1,1,法定节假日!$B$2:$B$67) | L30: 12 | P30: =NETWORKDAYS(N30,O30) | S30: 未完成
D31: 测试用例制定与确认 | J31: =_xlfn.WORKDAY.INTL(K30,1,1,法定节假日!$B$2:$B$67) | K31: =_xlfn.WORKDAY.INTL(J31,L31-1,1,法定节假日!$B$2:$B$67) | L31: 10 | P31: =NETWORKDAYS(N31,O31) | S31: 未完成
D32: 测试数据准备与确认 | J32: =_xlfn.WORKDAY.INTL(K31,1,1,法定节假日!$B$2:$B$67) | K32: =_xlfn.WORKDAY.INTL(J32,L32-1,1,法定节假日!$B$2:$B$67) | L32: 8 | P32: =NETWORKDAYS(N32,O32) | S32: 未完成
D33: 系统功能及优化确认 | J33: =_xlfn.WORKDAY.INTL(K32,1,1,法定节假日!$B$2:$B$67) | K33: =_xlfn.WORKDAY.INTL(J33,L33-1,1,法定节假日!$B$2:$B$67) | L33: 11 | P33: =NETWORKDAYS(N33,O33) | S33: 未完成
D34: 场景测试与报告确认 | J34: =_xlfn.WORKDAY.INTL(K33,1,1,法定节假日!$B$2:$B$67) | K34: =_xlfn.WORKDAY.INTL(J34,L34-1,1,法定节假日!$B$2:$B$67) | L34: =L29-SUM(L30:L33) | P34: =NETWORKDAYS(N34,O34) | S34: 未完成
B35: 3.3.3 | C35: 系统联调测试（全量） | J35: =主计划!N60 | K35: =主计划!O60 | L35: =主计划!P60 | N35: =MIN(N36:N40) | O35: =MAX(O36:O40) | P35: =NETWORKDAYS(N35,O35) | Q35: 宋沛霖 | S35: =IF(COUNTIF(S36:S40,"未完成")=COUNTA(S36:S40),"未完成",IF(COUNTIF(S36:S40,"已完成")=COUNTA(S36:S40),"已完成","进行中"))
D36: 联调测试计划制定与确认 | J36: =J35 | K36: =_xlfn.WORKDAY.INTL(J36,L36-1,1,法定节假日!$B$2:$B$67) | L36: 2 | P36: =NETWORKDAYS(N36,O36) | S36: 未完成
D37: 测试用例制定与确认 | J37: =_xlfn.WORKDAY.INTL(K36,1,1,法定节假日!$B$2:$B$67) | K37: =_xlfn.WORKDAY.INTL(J37,L37-1,1,法定节假日!$B$2:$B$67) | L37: 2 | P37: =NETWORKDAYS(N37,O37) | S37: 未完成
D38: 测试数据准备与确认 | J38: =_xlfn.WORKDAY.INTL(K37,1,1,法定节假日!$B$2:$B$67) | K38: =_xlfn.WORKDAY.INTL(J38,L38-1,1,法定节假日!$B$2:$B$67) | L38: 2 | P38: =NETWORKDAYS(N38,O38) | S38: 未完成
D39: 系统配置与通讯准备 | J39: =_xlfn.WORKDAY.INTL(K38,1,1,法定节假日!$B$2:$B$67) | K39: =_xlfn.WORKDAY.INTL(J39,L39-1,1,法定节假日!$B$2:$B$67) | L39: 2 | P39: =NETWORKDAYS(N39,O39) | S39: 未完成
D40: 接口测试与报告确认 | J40: =_xlfn.WORKDAY.INTL(K39,1,1,法定节假日!$B$2:$B$67) | K40: =_xlfn.WORKDAY.INTL(J40,L40-1,1,法定节假日!$B$2:$B$67) | L40: =L35-SUM(L36:L39) | P40: =NETWORKDAYS(N40,O40) | S40: 未完成
...

Sheet UAT试运行WBS
A1: 二级流程 （场景） | B1: 三级流程 （任务） | C1: 任务名称 | D1: WBS | E1: 说明 | F1: 里程碑 | G1: 乙方 评审 | H1: 甲方 评审 | I1: PMO 监控&评审点 | J1: 计划时间 | L1: 工作日 | M1: 是否与上个任务为前后置关系 | N1: 实际时间 | P1: 工作日 | Q1: 执行人 | S1: 进度 | U1: 交付物
J2: 计划开始 | K2: 计划结束 | L2: 计划天数 | N2: 实际开始 | O2: 实际完成 | P2: 实际天数 | Q2: 主责 | R2: 协助或支持 | S2: 状态 | T2: 进度备注
A3: 4.1 | C3: UAT/试运行 | J3: =主计划!N64 | K3: =主计划!O64 | L3: =主计划!P64 | N3: =MIN(N4:N15) | O3: =MAX(O4:O15) | P3: =NETWORKDAYS(N3,O3) | Q3: 陈本鸿 | S3: =IF(COUNTIF(S4:S15,"未完成")=COUNTA(S4:S15),"未完成",IF(COUNTIF(S4:S15,"已完成")=COUNTA(S4:S15),"已完成","进行中"))
B4: 4.1.1 | C4: 试运行计划制定 | J4: =主计划!N65 | K4: =主计划!O65 | L4: =主计划!P65 | N4: =MIN(N5:N5) | O4: =MAX(O5:O5) | P4: =NETWORKDAYS(N4,O4) | Q4: 陈本鸿 | S4: =IF(COUNTIF(S5:S5,"未完成")=COUNTA(S5:S5),"未完成",IF(COUNTIF(S5:S5,"已完成")=COUNTA(S5:S5),"已完成","进行中"))
D5: 试运行计划制定与确认 | G5: √ | H5: √ | I5: √ | J5: =J4 | K5: =_xlfn.WORKDAY.INTL(J5,L5-1,1,法定节假日!$B$2:$B$67) | L5: =L4 | P5: =NETWORKDAYS(N5,O5) | S5: 未完成
B6: 4.1.2 | C6: 全量数据测试准备 | J6: =主计划!N66 | K6: =主计划!O66 | L6: =主计划!P66 | N6: =MIN(N7:N10) | O6: =MAX(O7:O10) | P6: =NETWORKDAYS(N6,O6) | Q6: 宋沛霖 | S6: =IF(COUNTIF(S7:S10,"未完成")=COUNTA(S7:S10),"未完成",IF(COUNTIF(S7:S10,"已完成")=COUNTA(S7:S10),"已完成","进行中"))
D7: 产品与规则系统导入与验证 | J7: =J6 | K7: =_xlfn.WORKDAY.INTL(J7,L7-1,1,法定节假日!$B$2:$B$67) | L7: 1 | P7: =NETWORKDAYS(N7,O7) | S7: 未完成
D8: 业务数据全量导入 | J8: =_xlfn.WORKDAY.INTL(K7,1,1,法定节假日!$B$2:$B$67) | K8: =_xlfn.WORKDAY.INTL(J8,L8-1,1,法定节假日!$B$2:$B$67) | L8: 1 | P8: =NETWORKDAYS(N8,O8) | S8: 未完成
D9: 销售数据准备与导入 | J9: =_xlfn.WORKDAY.INTL(K8,1,1,法定节假日!$B$2:$B$67) | K9: =_xlfn.WORKDAY.INTL(J9,L9-1,1,法定节假日!$B$2:$B$67) | L9: 1 | P9: =NETWORKDAYS(N9,O9) | S9: 未完成
D10: 全量系统优化排产验证 | J10: =_xlfn.WORKDAY.INTL(K9,1,1,法定节假日!$B$2:$B$67) | K10: =_xlfn.WORKDAY.INTL(J10,L10-1,1,法定节假日!$B$2:$B$67) | L10: =L6-SUM(L7:L9) | P10: =NETWORKDAYS(N10,O10) | S10: 未完成
B11: 4.1.3 | C11: 系统试运行及确认 | J11: =主计划!N67 | K11: =主计划!O67 | L11: =主计划!P67 | N11: =MIN(N12:N13) | O11: =MAX(O12:O13) | P11: =NETWORKDAYS(N11,O11) | Q11: 陈本鸿 | S11: =IF(COUNTIF(S12:S13,"未完成")=COUNTA(S12:S13),"未完成",IF(COUNTIF(S12:S13,"已完成")=COUNTA(S12:S13),"已完成","进行中"))
D12: 各计划结果合理性确认 | J12: =J11 | K12: =_xlfn.WORKDAY.INTL(J12,L12-1,1,法定节假日!$B$2:$B$67) | L12: 70 | P12: =NETWORKDAYS(N12,O12) | S12: 未完成
D13: 试运行报告签字确认 | H13: √ | I13: √ | J13: =_xlfn.WORKDAY.INTL(K12,1,1,法定节假日!$B$2:$B$67) | K13: =_xlfn.WORKDAY.INTL(J13,L13-1,1,法定节假日!$B$2:$B$67) | L13: =L11-SUM(L12:L12) | P13: =NETWORKDAYS(N13,O13) | S13: 未完成
B14: 4.1.6 | C14: 测试问题结果确认 | J14: =主计划!N70 | K14: =主计划!O70 | L14: =主计划!P70 | N14: =MIN(N15:N15) | O14: =MAX(O15:O15) | P14: =NETWORKDAYS(N14,O14) | Q14: 陈本鸿 | S14: =IF(COUNTIF(S15:S15,"未完成")=COUNTA(S15:S15),"未完成",IF(COUNTIF(S15:S15,"已完成")=COUNTA(S15:S15),"已完成","进行中"))
D15: 测试问题结果确认 | J15: =J14 | K15: =_xlfn.WORKDAY.INTL(J15,L15-1,1,法定节假日!$B$2:$B$67) | L15: =L14 | P15: =NETWORKDAYS(N15,O15) | S15: 未完成
A16: 4.2 | C16: 最终用户培训 | J16: =主计划!N71 | K16: =主计划!O71 | L16: =主计划!P71 | N16: =MIN(N17:N21) | O16: =MAX(O17:O21) | P16: =NETWORKDAYS(N16,O16) | Q16: 陈本鸿 | S16: =IF(COUNTIF(S17:S21,"未完成")=COUNTA(S17:S21),"未完成",IF(COUNTIF(S17:S21,"已完成")=COUNTA(S17:S21),"已完成","进行中"))
B17: 4.2.1 | C17: 最终用户培训考核 | J17: =主计划!N72 | K17: =主计划!O72 | L17: =主计划!P72 | N17: =MIN(N18:N19) | O17: =MAX(O18:O19) | P17: =NETWORKDAYS(N17,O17) | Q17: 陈本鸿 | S17: =IF(COUNTIF(S18:S19,"未完成")=COUNTA(S18:S19),"未完成",IF(COUNTIF(S18:S19,"已完成")=COUNTA(S18:S19),"已完成","进行中"))
D18: 最终用户培训准备 | J18: =J17 | K18: =_xlfn.WORKDAY.INTL(J18,L18-1,1,法定节假日!$B$2:$B$67) | L18: 2 | P18: =NETWORKDAYS(N18,O18) | S18: 未完成
D19: 最终用户培训与考核 | J19: =_xlfn.WORKDAY.INTL(K18,1,1,法定节假日!$B$2:$B$67) | K19: =_xlfn.WORKDAY.INTL(J19,L19-1,1,法定节假日!$B$2:$B$67) | L19: =L17-SUM(L18:L18) | P19: =NETWORKDAYS(N19,O19) | S19: 未完成
B20: 4.2.2 | C20: 用户操作手册制定 | J20: =主计划!N73 | K20: =主计划!O73 | L20: =主计划!P73 | N20: =MIN(N21:N21) | O20: =MAX(O21:O21) | P20: =NETWORKDAYS(N20,O20) | Q20: 陈本鸿 | S20: =IF(COUNTIF(S21:S21,"未完成")=COUNTA(S21:S21),"未完成",IF(COUNTIF(S21:S21,"已完成")=COUNTA(S21:S21),"已完成","进行中"))
D21: 操作手册撰写与顾问评审 | G21: √ | H21: √ | I21: √ | J21: =J20 | K21: =_xlfn.WORKDAY.INTL(J21,L21-1,1,法定节假日!$B$2:$B$67) | L21: =L20 | P21: =NETWORKDAYS(N21,O21) | S21: 未完成
A22: 4.3 | C22: 上线准备 | J22: =主计划!N74 | K22: =主计划!O74 | L22: =主计划!P74 | N22: =MIN(N23:N39) | O22: =MAX(O23:O39) | P22: =NETWORKDAYS(N22,O22) | Q22: 陈本鸿 | S22: =IF(COUNTIF(S23:S39,"未完成")=COUNTA(S23:S39),"未完成",IF(COUNTIF(S23:S39,"已完成")=COUNTA(S23:S39),"已完成","进行中"))
B23: 4.3.1 | C23: 制定上线策略与切换计划 | J23: =主计划!N75 | K23: =主计划!O75 | L23: =主计划!P75 | N23: =MIN(N24:N25) | O23: =MAX(O24:O25) | P23: =NETWORKDAYS(N23,O23) | Q23: 陈本鸿 | S23: =IF(COUNTIF(S24:S25,"未完成")=COUNTA(S24:S25),"未完成",IF(COUNTIF(S24:S25,"已完成")=COUNTA(S24:S25),"已完成","进行中"))
D24: 上线策略与切换计划制定 | G24: √ | H24: √ | I24: √ | J24: =J23 | K24: =_xlfn.WORKDAY.INTL(J24,L24-1,1,法定节假日!$B$2:$B$67) | L24: 5 | P24: =NETWORKDAYS(N24,O24) | S24: 未完成
D25: 上线应急策略制定 | H25: √ | J25: =_xlfn.WORKDAY.INTL(K24,1,1,法定节假日!$B$2:$B$67) | K25: =_xlfn.WORKDAY.INTL(J25,L25-1,1,法定节假日!$B$2:$B$67) | L25: =L23-SUM(L24:L24) | P25: =NETWORKDAYS(N25,O25) | S25: 未完成
B26: 4.3.2 | C26: 初始化数据准备与测试 | J26: =主计划!N76 | K26: =主计划!O76 | L26: =主计划!P76 | N26: =MIN(N27:N29) | O26: =MAX(O27:O29) | P26: =NETWORKDAYS(N26,O26) | Q26: 宋沛霖 | S26: =IF(COUNTIF(S27:S29,"未完成")=COUNTA(S27:S29),"未完成",IF(COUNTIF(S27:S29,"已完成")=COUNTA(S27:S29),"已完成","进行中"))
D27: 初始化数据清单确认 | J27: =J26 | K27: =_xlfn.WORKDAY.INTL(J27,L27-1,1,法定节假日!$B$2:$B$67) | L27: 2 | P27: =NETWORKDAYS(N27,O27) | S27: 未完成
D28: 初始化数据验证指南 | J28: =_xlfn.WORKDAY.INTL(K27,1,1,法定节假日!$B$2:$B$67) | K28: =_xlfn.WORKDAY.INTL(J28,L28-1,1,法定节假日!$B$2:$B$67) | L28: 4 | P28: =NETWORKDAYS(N28,O28) | S28: 未完成
D29: xxxx数据收集与测试 | J29: =_xlfn.WORKDAY.INTL(K28,1,1,法定节假日!$B$2:$B$67) | K29: =_xlfn.WORKDAY.INTL(J29,L29-1,1,法定节假日!$B$2:$B$67) | L29: =L26-SUM(L27:L28) | P29: =NETWORKDAYS(N29,O29) | S29: 未完成
B30: 4.3.3 | C30: 准备正式生产环境 | J30: =主计划!N77 | K30: =主计划!O77 | L30: =主计划!P77 | N30: =MIN(N31:N37) | O30: =MAX(O31:O37) | P30: =NETWORKDAYS(N30,O30) | Q30: 陈本鸿 | S30: =IF(COUNTIF(S31:S37,"未完成")=COUNTA(S31:S37),"未完成",IF(COUNTIF(S31:S37,"已完成")=COUNTA(S31:S37),"已完成","进行中"))
D31: 服务器配置确认 | J31: =J30 | K31: =_xlfn.WORKDAY.INTL(J31,L31-1,1,法定节假日!$B$2:$B$67) | L31: 1 | P31: =NETWORKDAYS(N31,O31) | S31: 未完成
D32: 服务器端口开放确认 | J32: =_xlfn.WORKDAY.INTL(K31,1,1,法定节假日!$B$2:$B$67) | K32: =_xlfn.WORKDAY.INTL(J32,L32-1,1,法定节假日!$B$2:$B$67) | L32: 1 | P32: =NETWORKDAYS(N32,O32) | S32: 未完成
D33: 平台部署与自查 | J33: =_xlfn.WORKDAY.INTL(K32,1,1,法定节假日!$B$2:$B$67) | K33: =_xlfn.WORKDAY.INTL(J33,L33-1,1,法定节假日!$B$2:$B$67) | L33: 2 | P33: =NETWORKDAYS(N33,O33) | S33: 未完成
D34: 模型部署与检查 | J34: =_xlfn.WORKDAY.INTL(K33,1,1,法定节假日!$B$2:$B$67) | K34: =_xlfn.WORKDAY.INTL(J34,L34-1,1,法定节假日!$B$2:$B$67) | L34: 2 | P34: =NETWORKDAYS(N34,O34) | S34: 未完成
D35: 数据库安装与检查 | J35: =_xlfn.WORKDAY.INTL(K34,1,1,法定节假日!$B$2:$B$67) | K35: =_xlfn.WORKDAY.INTL(J35,L35-1,1,法定节假日!$B$2:$B$67) | L35: 2 | P35: =NETWORKDAYS(N35,O35) | S35: 未完成
D36: 系统登录确认 | J36: =_xlfn.WORKDAY.INTL(K35,1,1,法定节假日!$B$2:$B$67) | K36: =_xlfn.WORKDAY.INTL(J36,L36-1,1,法定节假日!$B$2:$B$67) | L36: 1 | P36: =NETWORKDAYS(N36,O36) | S36: 未完成
D37: 网络通畅确认 | J37: =_xlfn.WORKDAY.INTL(K36,1,1,法定节假日!$B$2:$B$67) | K37: =_xlfn.WORKDAY.INTL(J37,L37-1,1,法定节假日!$B$2:$B$67) | L37: =L30-SUM(L31:L36) | P37: =NETWORKDAYS(N37,O37) | S37: 未完成
B38: 4.3.4 | C38: 上线启动商讨会 | J38: =主计划!N78 | K38: =主计划!O78 | L38: =主计划!P78 | N38: =MIN(N39:N39) | O38: =MAX(O39:O39) | P38: =NETWORKDAYS(N38,O38) | Q38: 周年根 | S38: =IF(COUNTIF(S39:S39,"未完成")=COUNTA(S39:S39),"未完成",IF(COUNTIF(S39:S39,"已完成")=COUNTA(S39:S39),"已完成","进行中"))
D39: 上线启动商讨会 | J39: =J38 | K39: =_xlfn.WORKDAY.INTL(J39,L39-1,1,法定节假日!$B$2:$B$67) | L39: =L38 | P39: =NETWORKDAYS(N39,O39) | S39: 未完成
A40: 4.4 | C40: 系统上线 | J40: =主计划!N79 | K40: =主计划!O79 | L40: =主计划!P79 | N40: =MIN(N41:N51) | O40: =MAX(O41:O51) | P40: =NETWORKDAYS(N40,O40) | Q40: 周年根 | S40: =IF(COUNTIF(S41:S51,"未完成")=COUNTA(S41:S51),"未完成",IF(COUNTIF(S41:S51,"已完成")=COUNTA(S41:S51),"已完成","进行中"))
...

Sheet 上线运行WBS
A1: 二级流程 （场景） | B1: 三级流程 （任务） | C1: 任务名称 | D1: WBS | E1: 说明 | F1: 里程碑 | G1: 乙方 评审 | H1: 甲方 评审 | I1: PMO 监控&评审点 | J1: 计划时间 | L1: 工作日 | M1: 是否与上个任务为前后置关系 | N1: 实际时间 | P1: 工作日 | Q1: 执行人 | S1: 进度 | U1: 交付物
J2: 计划开始 | K2: 计划结束 | L2: 计划天数 | N2: 实际开始 | O2: 实际完成 | P2: 实际天数 | Q2: 主责 | R2: 协助或支持 | S2: 状态 | T2: 进度备注
A3: 5.1 | C3: 辅导与验收 | J3: =主计划!N85 | K3: =主计划!O85 | L3: =主计划!P85 | N3: =MIN(N4:N22) | O3: =MAX(O4:O22) | P3: =NETWORKDAYS(N3,O3) | Q3: 周年根 | S3: =IF(COUNTIF(S4:S22,"未完成")=COUNTA(S4:S22),"未完成",IF(COUNTIF(S4:S22,"已完成")=COUNTA(S4:S22),"已完成","进行中"))
B4: 5.1.1 | C4: 验收策略确认 | I4: √ | J4: =主计划!N86 | K4: =主计划!O86 | L4: =主计划!P86 | P4: =NETWORKDAYS(N4,O4) | Q4: 周年根 | S4: 未完成
B5: 5.1.2 | C5: 用户应用指导与定期复盘 | J5: =主计划!N87 | K5: =主计划!O87 | L5: =主计划!P87 | N5: =MIN(N6:N8) | O5: =MAX(O6:O8) | P5: =NETWORKDAYS(N5,O5) | Q5: 陈本鸿 | S5: =IF(COUNTIF(S6:S8,"未完成")=COUNTA(S6:S8),"未完成",IF(COUNTIF(S6:S8,"已完成")=COUNTA(S6:S8),"已完成","进行中"))
D6: 项目复盘材料制定 | J6: =J5 | K6: =_xlfn.WORKDAY.INTL(J6,L6-1,1,法定节假日!$B$2:$B$67) | L6: 25 | P6: =NETWORKDAYS(N6,O6) | S6: 未完成
D7: 组织召开复盘会议 | J7: =_xlfn.WORKDAY.INTL(K6,1,1,法定节假日!$B$2:$B$67) | K7: =_xlfn.WORKDAY.INTL(J7,L7-1,1,法定节假日!$B$2:$B$67) | L7: 11 | P7: =NETWORKDAYS(N7,O7) | S7: 未完成
D8: 总结问题并发布指导手册 | J8: =_xlfn.WORKDAY.INTL(K7,1,1,法定节假日!$B$2:$B$67) | K8: =_xlfn.WORKDAY.INTL(J8,L8-1,1,法定节假日!$B$2:$B$67) | L8: =L5-SUM(L6:L7) | P8: =NETWORKDAYS(N8,O8) | S8: 未完成
B9: 5.1.3 | C9: 实施文档基线确认 | J9: =主计划!N88 | K9: =主计划!O88 | L9: =主计划!P88 | N9: =MIN(N10:N13) | O9: =MAX(O10:O13) | P9: =NETWORKDAYS(N9,O9) | Q9: 陈本鸿 | S9: =IF(COUNTIF(S10:S13,"未完成")=COUNTA(S10:S13),"未完成",IF(COUNTIF(S10:S13,"已完成")=COUNTA(S10:S13),"已完成","进行中"))
D10: 确认交付文档清单 | J10: =J9 | K10: =_xlfn.WORKDAY.INTL(J10,L10-1,1,法定节假日!$B$2:$B$67) | L10: 15 | P10: =NETWORKDAYS(N10,O10) | S10: 未完成
D11: 整理项目交付文档 | J11: =_xlfn.WORKDAY.INTL(K10,1,1,法定节假日!$B$2:$B$67) | K11: =_xlfn.WORKDAY.INTL(J11,L11-1,1,法定节假日!$B$2:$B$67) | L11: 15 | P11: =NETWORKDAYS(N11,O11) | S11: 未完成
D12: URS需求应答-状态确认 | J12: =_xlfn.WORKDAY.INTL(K11,1,1,法定节假日!$B$2:$B$67) | K12: =_xlfn.WORKDAY.INTL(J12,L12-1,1,法定节假日!$B$2:$B$67) | L12: 11 | P12: =NETWORKDAYS(N12,O12) | S12: 未完成
D13: 项目文档基线确认 | J13: =_xlfn.WORKDAY.INTL(K12,1,1,法定节假日!$B$2:$B$67) | K13: =_xlfn.WORKDAY.INTL(J13,L13-1,1,法定节假日!$B$2:$B$67) | L13: =L9-SUM(L10:L12) | P13: =NETWORKDAYS(N13,O13) | S13: 未完成
B14: 5.1.4 | C14: 项目验收评审 | J14: =主计划!N89 | K14: =主计划!O89 | L14: =主计划!P89 | N14: =MIN(N15:N16) | O14: =MAX(O15:O16) | P14: =NETWORKDAYS(N14,O14) | Q14: 周年根 | S14: =IF(COUNTIF(S15:S16,"未完成")=COUNTA(S15:S16),"未完成",IF(COUNTIF(S15:S16,"已完成")=COUNTA(S15:S16),"已完成","进行中"))
D15: 准备验收评审材料 | G15: √ | H15: √ | I15: √ | J15: =J14 | K15: =_xlfn.WORKDAY.INTL(J15,L15-1,1,法定节假日!$B$2:$B$67) | L15: 37 | P15: =NETWORKDAYS(N15,O15) | S15: 未完成
D16: 组织项目验收评审 | H16: √ | J16: =_xlfn.WORKDAY.INTL(K15,1,1,法定节假日!$B$2:$B$67) | K16: =_xlfn.WORKDAY.INTL(J16,L16-1,1,法定节假日!$B$2:$B$67) | L16: =L14-SUM(L15:L15) | P16: =NETWORKDAYS(N16,O16) | S16: 未完成
B17: 5.1.5 | C17: 召开项目总结表彰 | J17: =主计划!N90 | K17: =主计划!O90 | L17: =主计划!P90 | N17: =MIN(N18:N20) | O17: =MAX(O18:O20) | P17: =NETWORKDAYS(N17,O17) | Q17: 周年根 | S17: =IF(COUNTIF(S18:S20,"未完成")=COUNTA(S18:S20),"未完成",IF(COUNTIF(S18:S20,"已完成")=COUNTA(S18:S20),"已完成","进行中"))
D18: 会议流程讨论 | J18: =J17 | K18: =_xlfn.WORKDAY.INTL(J18,L18-1,1,法定节假日!$B$2:$B$67) | L18: 12 | P18: =NETWORKDAYS(N18,O18) | S18: 未完成
D19: 表彰会材料制作与同行评审 | G19: √ | H19: √ | I19: √ | J19: =_xlfn.WORKDAY.INTL(K18,1,1,法定节假日!$B$2:$B$67) | K19: =_xlfn.WORKDAY.INTL(J19,L19-1,1,法定节假日!$B$2:$B$67) | L19: 28 | P19: =NETWORKDAYS(N19,O19) | S19: 未完成
D20: 召开项目总结表彰会 | J20: =_xlfn.WORKDAY.INTL(K19,1,1,法定节假日!$B$2:$B$67) | K20: =_xlfn.WORKDAY.INTL(J20,L20-1,1,法定节假日!$B$2:$B$67) | L20: =L17-SUM(L18:L19) | P20: =NETWORKDAYS(N20,O20) | S20: 未完成
B21: 5.1.6 | C21: 签署验收确认单 | J21: =主计划!N91 | K21: =主计划!O91 | L21: =主计划!P91 | N21: =MIN(N22:N22) | O21: =MAX(O22:O22) | P21: =NETWORKDAYS(N21,O21) | Q21: 周年根 | S21: =IF(COUNTIF(S22:S22,"未完成")=COUNTA(S22:S22),"未完成",IF(COUNTIF(S22:S22,"已完成")=COUNTA(S22:S22),"已完成","进行中"))
D22: 签署验收确认单 | F22: √ | I22: √ | J22: =J21 | K22: =_xlfn.WORKDAY.INTL(J22,L22-1,1,法定节假日!$B$2:$B$67) | L22: =L21 | P22: =NETWORKDAYS(N22,O22) | S22: 未完成
A23: 5.2 | C23: 项目收尾 | J23: =主计划!N92 | K23: =主计划!O92 | N23: =MIN(N24:N32) | O23: =MAX(O24:O32) | P23: =NETWORKDAYS(N23,O23) | Q23: 周年根 | S23: =IF(COUNTIF(S24:S32,"未完成")=COUNTA(S24:S32),"未完成",IF(COUNTIF(S24:S32,"已完成")=COUNTA(S24:S32),"已完成","进行中"))
B24: 5.2.1 | C24: 移交项目资料给客户 | J24: =主计划!N93 | K24: =主计划!O93 | L24: =主计划!P93 | P24: =NETWORKDAYS(N24,O24) | Q24: 陈本鸿 | S24: 未完成
B25: 5.2.2 | C25: 内部分享与总结归档 | J25: =主计划!N94 | K25: =主计划!O94 | L25: =主计划!P94 | N25: =MIN(N26:N28) | O25: =MAX(O26:O28) | P25: =NETWORKDAYS(N25,O25) | Q25: 陈本鸿 | S25: =IF(COUNTIF(S26:S28,"未完成")=COUNTA(S26:S28),"未完成",IF(COUNTIF(S26:S28,"已完成")=COUNTA(S26:S28),"已完成","进行中"))
D26: 系统功能分享-内部 | I26: √ | J26: =J25 | K26: =_xlfn.WORKDAY.INTL(J26,L26-1,1,法定节假日!$B$2:$B$67) | L26: 3 | P26: =NETWORKDAYS(N26,O26) | S26: 未完成
D27: 项目组工作总结-内部 | I27: √ | J27: =_xlfn.WORKDAY.INTL(K26,1,1,法定节假日!$B$2:$B$67) | K27: =_xlfn.WORKDAY.INTL(J27,L27-1,1,法定节假日!$B$2:$B$67) | L27: 2 | P27: =NETWORKDAYS(N27,O27) | S27: 未完成
D28: 更新组织过程资产-内部 | I28: √ | J28: =_xlfn.WORKDAY.INTL(K27,1,1,法定节假日!$B$2:$B$67) | K28: =_xlfn.WORKDAY.INTL(J28,L28-1,1,法定节假日!$B$2:$B$67) | L28: =L25-SUM(L26:L27) | P28: =NETWORKDAYS(N28,O28) | S28: 未完成
B29: 5.2.3 | C29: 奖惩兑现与团队解散 | J29: =主计划!N95 | K29: =主计划!O95 | L29: =主计划!P95 | P29: =NETWORKDAYS(N29,O29) | Q29: 周年根 | S29: 未完成
B30: 5.2.4 | C30: 实施转持续服务交接 | J30: =主计划!N96 | K30: =主计划!O96 | L30: =主计划!P96 | N30: =MIN(N31:N32) | O30: =MAX(O31:O32) | P30: =NETWORKDAYS(N30,O30) | Q30: 陈本鸿 | S30: =IF(COUNTIF(S31:S32,"未完成")=COUNTA(S31:S32),"未完成",IF(COUNTIF(S31:S32,"已完成")=COUNTA(S31:S32),"已完成","进行中"))
D31: 实施转持续服务交接 | I31: √ | J31: =J30 | K31: =_xlfn.WORKDAY.INTL(J31,L31-1,1,法定节假日!$B$2:$B$67) | L31: 4 | P31: =NETWORKDAYS(N31,O31) | S31: 未完成
D32: 平台永久授权申请 | J32: =_xlfn.WORKDAY.INTL(K31,1,1,法定节假日!$B$2:$B$67) | K32: =_xlfn.WORKDAY.INTL(J32,L32-1,1,法定节假日!$B$2:$B$67) | L32: =L30-SUM(L31:L31) | P32: =NETWORKDAYS(N32,O32) | S32: 未完成

Sheet 法定节假日
B1: 日期
A2: 元旦 | B2: 46021 | C2: 2026假日
B3: 46022
B4: 46023
A5: 春节 | B5: 46068
B6: 46069
B7: 46070
B8: 46071
B9: 46072
B10: 46073
B11: 46074
B12: 46075
B13: 46076
A14: 清明节 | B14: 46116
B15: 46117
B16: 46118
A17: 劳动节 | B17: 46143
B18: 46144
B19: 46145
B20: 46146
B21: 46147
A22: 端午节 | B22: 46192
B23: 46193
B24: 46194
A25: 中秋节 | B25: 46290
B26: 46291
B27: 46292
A28: 国庆节 | B28: 46296
B29: 46297
B30: 46298
B31: 46299
B32: 46300
B33: 46301
B34: 46302
A35: 元旦 | B35: 46386 | C35: 2027假日
B36: 46387
B37: 46388
A38: 春节 | B38: 46422
B39: 46423
B40: 46424
...
